{
  "version": 8,
  "blockIdVersion": 11,
  "anchorX": 0,
  "anchorY": 0,
  "anchorZ": 0,
  "blocks": [
    {
      "x": -22,
      "y": 0,
      "z": -22,
      "name": "Empty"
    },
    {
      "x": -22,
      "y": 0,
      "z": -21,
      "name": "Empty"
    },
    {
      "x": -22,
      "y": 0,
      "z": -20,
      "name": "Empty"
    },
    {
      "x": -22,
      "y": 0,
      "z": -19,
      "name": "Empty"
    },
    {
      "x": -22,
      "y": 0,
      "z": -18,
      "name": "Empty"
    },
    {
      "x": -22,
      "y": 0,
      "z": -17,
      "name": "Empty"
    },
    {
      "x": -22,
      "y": 0,
      "z": -16,
      "name": "Empty"
    },
    {
      "x": -22,
      "y": 0,
      "z": -15,
      "name": "Empty"
    },
    {
      "x": -22,
      "y": 0,
      "z": -14,
      "name": "Empty"
    },
    {
      "x": -22,
      "y": 0,
      "z": -13,
      "name": "Empty"
    },
    {
      "x": -22,
      "y": 0,
      "z": -12,
      "name": "Empty"
    },
    {
      "x": -22,
      "y": 0,
      "z": -11,
      "name": "Empty"
    },
    {
      "x": -22,
      "y": 0,
      "z": -10,
      "name": "Empty"
    },
    {
      "x": -22,
      "y": 0,
      "z": -9,
      "name": "Empty"
    },
    {
      "x": -22,
      "y": 0,
      "z": -8,
      "name": "Empty"
    },
    {
      "x": -22,
      "y": 0,
      "z": -7,
      "name": "Empty"
    },
    {
      "x": -22,
      "y": 0,
      "z": -6,
      "name": "Empty"
    },
    {
      "x": -22,
      "y": 0,
      "z": -5,
      "name": "Empty"
    },
    {
      "x": -22,
      "y": 0,
      "z": -4,
      "name": "Empty"
    },
    {
      "x": -22,
      "y": 0,
      "z": -3,
      "name": "Empty"
    },
    {
      "x": -22,
      "y": 0,
      "z": -2,
      "name": "Empty"
    },
    {
      "x": -22,
      "y": 0,
      "z": -1,
      "name": "Empty"
    },
    {
      "x": -22,
      "y": 0,
      "z": 0,
      "name": "Empty"
    },
    {
      "x": -22,
      "y": 0,
      "z": 1,
      "name": "Empty"
    },
    {
      "x": -22,
      "y": 0,
      "z": 2,
      "name": "Empty"
    },
    {
      "x": -22,
      "y": 0,
      "z": 3,
      "name": "Empty"
    },
    {
      "x": -22,
      "y": 0,
      "z": 4,
      "name": "Empty"
    },
    {
      "x": -22,
      "y": 0,
      "z": 5,
      "name": "Empty"
    },
    {
      "x": -22,
      "y": 0,
      "z": 6,
      "name": "Empty"
    },
    {
      "x": -22,
      "y": 0,
      "z": 7,
      "name": "Empty"
    },
    {
      "x": -22,
      "y": 0,
      "z": 8,
      "name": "Empty"
    },
    {
      "x": -22,
      "y": 0,
      "z": 9,
      "name": "Empty"
    },
    {
      "x": -22,
      "y": 0,
      "z": 10,
      "name": "Empty"
    },
    {
      "x": -22,
      "y": 0,
      "z": 11,
      "name": "Empty"
    },
    {
      "x": -22,
      "y": 0,
      "z": 12,
      "name": "Empty"
    },
    {
      "x": -22,
      "y": 0,
      "z": 13,
      "name": "Empty"
    },
    {
      "x": -22,
      "y": 0,
      "z": 14,
      "name": "Empty"
    },
    {
      "x": -22,
      "y": 0,
      "z": 15,
      "name": "Empty"
    },
    {
      "x": -22,
      "y": 0,
      "z": 16,
      "name": "Empty"
    },
    {
      "x": -22,
      "y": 0,
      "z": 17,
      "name": "Empty"
    },
    {
      "x": -22,
      "y": 0,
      "z": 18,
      "name": "Empty"
    },
    {
      "x": -22,
      "y": 0,
      "z": 19,
      "name": "Empty"
    },
    {
      "x": -22,
      "y": 0,
      "z": 20,
      "name": "Empty"
    },
    {
      "x": -22,
      "y": 0,
      "z": 21,
      "name": "Empty"
    },
    {
      "x": -22,
      "y": 0,
      "z": 22,
      "name": "Empty"
    },
    {
      "x": -22,
      "y": 0,
      "z": 23,
      "name": "Empty"
    },
    {
      "x": -21,
      "y": 0,
      "z": -22,
      "name": "Empty"
    },
    {
      "x": -21,
      "y": 0,
      "z": -21,
      "name": "Empty"
    },
    {
      "x": -21,
      "y": 0,
      "z": -20,
      "name": "Empty"
    },
    {
      "x": -21,
      "y": 0,
      "z": -19,
      "name": "Empty"
    },
    {
      "x": -21,
      "y": 0,
      "z": -18,
      "name": "Empty"
    },
    {
      "x": -21,
      "y": 0,
      "z": -17,
      "name": "Empty"
    },
    {
      "x": -21,
      "y": 0,
      "z": -16,
      "name": "Empty"
    },
    {
      "x": -21,
      "y": 0,
      "z": -15,
      "name": "Empty"
    },
    {
      "x": -21,
      "y": 0,
      "z": -14,
      "name": "Empty"
    },
    {
      "x": -21,
      "y": 0,
      "z": -13,
      "name": "Empty"
    },
    {
      "x": -21,
      "y": 0,
      "z": -12,
      "name": "Empty"
    },
    {
      "x": -21,
      "y": 0,
      "z": -11,
      "name": "Empty"
    },
    {
      "x": -21,
      "y": 0,
      "z": -10,
      "name": "Empty"
    },
    {
      "x": -21,
      "y": 0,
      "z": -9,
      "name": "Empty"
    },
    {
      "x": -21,
      "y": 0,
      "z": -8,
      "name": "Empty"
    },
    {
      "x": -21,
      "y": 0,
      "z": -7,
      "name": "Empty"
    },
    {
      "x": -21,
      "y": 0,
      "z": -6,
      "name": "Empty"
    },
    {
      "x": -21,
      "y": 0,
      "z": -5,
      "name": "Empty"
    },
    {
      "x": -21,
      "y": 0,
      "z": -4,
      "name": "Empty"
    },
    {
      "x": -21,
      "y": 0,
      "z": -3,
      "name": "Empty"
    },
    {
      "x": -21,
      "y": 0,
      "z": -2,
      "name": "Empty"
    },
    {
      "x": -21,
      "y": 0,
      "z": -1,
      "name": "Empty"
    },
    {
      "x": -21,
      "y": 0,
      "z": 0,
      "name": "Empty"
    },
    {
      "x": -21,
      "y": 0,
      "z": 1,
      "name": "Empty"
    },
    {
      "x": -21,
      "y": 0,
      "z": 2,
      "name": "Empty"
    },
    {
      "x": -21,
      "y": 0,
      "z": 3,
      "name": "Empty"
    },
    {
      "x": -21,
      "y": 0,
      "z": 4,
      "name": "Empty"
    },
    {
      "x": -21,
      "y": 0,
      "z": 5,
      "name": "Empty"
    },
    {
      "x": -21,
      "y": 0,
      "z": 6,
      "name": "Empty"
    },
    {
      "x": -21,
      "y": 0,
      "z": 7,
      "name": "Empty"
    },
    {
      "x": -21,
      "y": 0,
      "z": 8,
      "name": "Empty"
    },
    {
      "x": -21,
      "y": 0,
      "z": 9,
      "name": "Empty"
    },
    {
      "x": -21,
      "y": 0,
      "z": 10,
      "name": "Empty"
    },
    {
      "x": -21,
      "y": 0,
      "z": 11,
      "name": "Empty"
    },
    {
      "x": -21,
      "y": 0,
      "z": 12,
      "name": "Empty"
    },
    {
      "x": -21,
      "y": 0,
      "z": 13,
      "name": "Empty"
    },
    {
      "x": -21,
      "y": 0,
      "z": 14,
      "name": "Empty"
    },
    {
      "x": -21,
      "y": 0,
      "z": 15,
      "name": "Empty"
    },
    {
      "x": -21,
      "y": 0,
      "z": 16,
      "name": "Empty"
    },
    {
      "x": -21,
      "y": 0,
      "z": 17,
      "name": "Empty"
    },
    {
      "x": -21,
      "y": 0,
      "z": 18,
      "name": "Empty"
    },
    {
      "x": -21,
      "y": 0,
      "z": 19,
      "name": "Empty"
    },
    {
      "x": -21,
      "y": 0,
      "z": 20,
      "name": "Empty"
    },
    {
      "x": -21,
      "y": 0,
      "z": 21,
      "name": "Empty"
    },
    {
      "x": -21,
      "y": 0,
      "z": 22,
      "name": "Empty"
    },
    {
      "x": -21,
      "y": 0,
      "z": 23,
      "name": "Empty"
    },
    {
      "x": -20,
      "y": 0,
      "z": -22,
      "name": "Empty"
    },
    {
      "x": -20,
      "y": 0,
      "z": -21,
      "name": "Empty"
    },
    {
      "x": -20,
      "y": 0,
      "z": -20,
      "name": "Empty"
    },
    {
      "x": -20,
      "y": 0,
      "z": -19,
      "name": "Empty"
    },
    {
      "x": -20,
      "y": 0,
      "z": -18,
      "name": "Empty"
    },
    {
      "x": -20,
      "y": 0,
      "z": -17,
      "name": "Empty"
    },
    {
      "x": -20,
      "y": 0,
      "z": -16,
      "name": "Empty"
    },
    {
      "x": -20,
      "y": 0,
      "z": -15,
      "name": "Empty"
    },
    {
      "x": -20,
      "y": 0,
      "z": -14,
      "name": "Empty"
    },
    {
      "x": -20,
      "y": 0,
      "z": -13,
      "name": "Empty"
    },
    {
      "x": -20,
      "y": 0,
      "z": -12,
      "name": "Empty"
    },
    {
      "x": -20,
      "y": 0,
      "z": -11,
      "name": "Empty"
    },
    {
      "x": -20,
      "y": 0,
      "z": -10,
      "name": "Empty"
    },
    {
      "x": -20,
      "y": 0,
      "z": -9,
      "name": "Empty"
    },
    {
      "x": -20,
      "y": 0,
      "z": -8,
      "name": "Empty"
    },
    {
      "x": -20,
      "y": 0,
      "z": -7,
      "name": "Empty"
    },
    {
      "x": -20,
      "y": 0,
      "z": -6,
      "name": "Empty"
    },
    {
      "x": -20,
      "y": 0,
      "z": -5,
      "name": "Empty"
    },
    {
      "x": -20,
      "y": 0,
      "z": -4,
      "name": "Empty"
    },
    {
      "x": -20,
      "y": 0,
      "z": -3,
      "name": "Empty"
    },
    {
      "x": -20,
      "y": 0,
      "z": -2,
      "name": "Empty"
    },
    {
      "x": -20,
      "y": 0,
      "z": -1,
      "name": "Empty"
    },
    {
      "x": -20,
      "y": 0,
      "z": 0,
      "name": "Empty"
    },
    {
      "x": -20,
      "y": 0,
      "z": 1,
      "name": "Empty"
    },
    {
      "x": -20,
      "y": 0,
      "z": 2,
      "name": "Empty"
    },
    {
      "x": -20,
      "y": 0,
      "z": 3,
      "name": "Empty"
    },
    {
      "x": -20,
      "y": 0,
      "z": 4,
      "name": "Empty"
    },
    {
      "x": -20,
      "y": 0,
      "z": 5,
      "name": "Empty"
    },
    {
      "x": -20,
      "y": 0,
      "z": 6,
      "name": "Empty"
    },
    {
      "x": -20,
      "y": 0,
      "z": 7,
      "name": "Empty"
    },
    {
      "x": -20,
      "y": 0,
      "z": 8,
      "name": "Empty"
    },
    {
      "x": -20,
      "y": 0,
      "z": 9,
      "name": "Empty"
    },
    {
      "x": -20,
      "y": 0,
      "z": 10,
      "name": "Empty"
    },
    {
      "x": -20,
      "y": 0,
      "z": 11,
      "name": "Empty"
    },
    {
      "x": -20,
      "y": 0,
      "z": 12,
      "name": "Empty"
    },
    {
      "x": -20,
      "y": 0,
      "z": 13,
      "name": "Empty"
    },
    {
      "x": -20,
      "y": 0,
      "z": 14,
      "name": "Empty"
    },
    {
      "x": -20,
      "y": 0,
      "z": 15,
      "name": "Empty"
    },
    {
      "x": -20,
      "y": 0,
      "z": 16,
      "name": "Empty"
    },
    {
      "x": -20,
      "y": 0,
      "z": 17,
      "name": "Empty"
    },
    {
      "x": -20,
      "y": 0,
      "z": 18,
      "name": "Empty"
    },
    {
      "x": -20,
      "y": 0,
      "z": 19,
      "name": "Empty"
    },
    {
      "x": -20,
      "y": 0,
      "z": 20,
      "name": "Empty"
    },
    {
      "x": -20,
      "y": 0,
      "z": 21,
      "name": "Empty"
    },
    {
      "x": -20,
      "y": 0,
      "z": 22,
      "name": "Empty"
    },
    {
      "x": -20,
      "y": 0,
      "z": 23,
      "name": "Empty"
    },
    {
      "x": -19,
      "y": 0,
      "z": -22,
      "name": "Empty"
    },
    {
      "x": -19,
      "y": 0,
      "z": -21,
      "name": "Empty"
    },
    {
      "x": -19,
      "y": 0,
      "z": -20,
      "name": "Empty"
    },
    {
      "x": -19,
      "y": 0,
      "z": -19,
      "name": "Empty"
    },
    {
      "x": -19,
      "y": 0,
      "z": -18,
      "name": "Empty"
    },
    {
      "x": -19,
      "y": 0,
      "z": -17,
      "name": "Empty"
    },
    {
      "x": -19,
      "y": 0,
      "z": -16,
      "name": "Empty"
    },
    {
      "x": -19,
      "y": 0,
      "z": -15,
      "name": "Empty"
    },
    {
      "x": -19,
      "y": 0,
      "z": -14,
      "name": "Empty"
    },
    {
      "x": -19,
      "y": 0,
      "z": -13,
      "name": "Empty"
    },
    {
      "x": -19,
      "y": 0,
      "z": -12,
      "name": "Empty"
    },
    {
      "x": -19,
      "y": 0,
      "z": -11,
      "name": "Empty"
    },
    {
      "x": -19,
      "y": 0,
      "z": -10,
      "name": "Empty"
    },
    {
      "x": -19,
      "y": 0,
      "z": -9,
      "name": "Empty"
    },
    {
      "x": -19,
      "y": 0,
      "z": -8,
      "name": "Empty"
    },
    {
      "x": -19,
      "y": 0,
      "z": -7,
      "name": "Empty"
    },
    {
      "x": -19,
      "y": 0,
      "z": -6,
      "name": "Empty"
    },
    {
      "x": -19,
      "y": 0,
      "z": -5,
      "name": "Empty"
    },
    {
      "x": -19,
      "y": 0,
      "z": -4,
      "name": "Empty"
    },
    {
      "x": -19,
      "y": 0,
      "z": -3,
      "name": "Empty"
    },
    {
      "x": -19,
      "y": 0,
      "z": -2,
      "name": "Empty"
    },
    {
      "x": -19,
      "y": 0,
      "z": -1,
      "name": "Empty"
    },
    {
      "x": -19,
      "y": 0,
      "z": 0,
      "name": "Empty"
    },
    {
      "x": -19,
      "y": 0,
      "z": 1,
      "name": "Empty"
    },
    {
      "x": -19,
      "y": 0,
      "z": 2,
      "name": "Empty"
    },
    {
      "x": -19,
      "y": 0,
      "z": 3,
      "name": "Empty"
    },
    {
      "x": -19,
      "y": 0,
      "z": 4,
      "name": "Empty"
    },
    {
      "x": -19,
      "y": 0,
      "z": 5,
      "name": "Empty"
    },
    {
      "x": -19,
      "y": 0,
      "z": 6,
      "name": "Empty"
    },
    {
      "x": -19,
      "y": 0,
      "z": 7,
      "name": "Empty"
    },
    {
      "x": -19,
      "y": 0,
      "z": 8,
      "name": "Empty"
    },
    {
      "x": -19,
      "y": 0,
      "z": 9,
      "name": "Empty"
    },
    {
      "x": -19,
      "y": 0,
      "z": 10,
      "name": "Empty"
    },
    {
      "x": -19,
      "y": 0,
      "z": 11,
      "name": "Empty"
    },
    {
      "x": -19,
      "y": 0,
      "z": 12,
      "name": "Empty"
    },
    {
      "x": -19,
      "y": 0,
      "z": 13,
      "name": "Empty"
    },
    {
      "x": -19,
      "y": 0,
      "z": 14,
      "name": "Empty"
    },
    {
      "x": -19,
      "y": 0,
      "z": 15,
      "name": "Empty"
    },
    {
      "x": -19,
      "y": 0,
      "z": 16,
      "name": "Empty"
    },
    {
      "x": -19,
      "y": 0,
      "z": 17,
      "name": "Empty"
    },
    {
      "x": -19,
      "y": 0,
      "z": 18,
      "name": "Empty"
    },
    {
      "x": -19,
      "y": 0,
      "z": 19,
      "name": "Empty"
    },
    {
      "x": -19,
      "y": 0,
      "z": 20,
      "name": "Empty"
    },
    {
      "x": -19,
      "y": 0,
      "z": 21,
      "name": "Empty"
    },
    {
      "x": -19,
      "y": 0,
      "z": 22,
      "name": "Empty"
    },
    {
      "x": -19,
      "y": 0,
      "z": 23,
      "name": "Empty"
    },
    {
      "x": -18,
      "y": 0,
      "z": -22,
      "name": "Empty"
    },
    {
      "x": -18,
      "y": 0,
      "z": -21,
      "name": "Empty"
    },
    {
      "x": -18,
      "y": 0,
      "z": -20,
      "name": "Empty"
    },
    {
      "x": -18,
      "y": 0,
      "z": -19,
      "name": "Empty"
    },
    {
      "x": -18,
      "y": 0,
      "z": -18,
      "name": "Empty"
    },
    {
      "x": -18,
      "y": 0,
      "z": -17,
      "name": "Empty"
    },
    {
      "x": -18,
      "y": 0,
      "z": -16,
      "name": "Empty"
    },
    {
      "x": -18,
      "y": 0,
      "z": -15,
      "name": "Empty"
    },
    {
      "x": -18,
      "y": 0,
      "z": -14,
      "name": "Empty"
    },
    {
      "x": -18,
      "y": 0,
      "z": -13,
      "name": "Empty"
    },
    {
      "x": -18,
      "y": 0,
      "z": -12,
      "name": "Empty"
    },
    {
      "x": -18,
      "y": 1,
      "z": -12,
      "name": "Rock_Volcanic_Brick",
      "rotation": 2
    },
    {
      "x": -18,
      "y": 2,
      "z": -12,
      "name": "Rock_Volcanic_Brick",
      "rotation": 2
    },
    {
      "x": -18,
      "y": 3,
      "z": -12,
      "name": "Rock_Volcanic_Brick",
      "rotation": 2
    },
    {
      "x": -18,
      "y": 4,
      "z": -12,
      "name": "Rock_Volcanic_Brick_Stairs",
      "rotation": 3
    },
    {
      "x": -18,
      "y": 0,
      "z": -11,
      "name": "Empty"
    },
    {
      "x": -18,
      "y": 1,
      "z": -11,
      "name": "Rock_Volcanic_Brick_Wall",
      "rotation": 3
    },
    {
      "x": -18,
      "y": 2,
      "z": -11,
      "name": "Rock_Volcanic_Cobble_Beam",
      "rotation": 3
    },
    {
      "x": -18,
      "y": 3,
      "z": -11,
      "name": "Rock_Volcanic_Brick_Beam",
      "rotation": 3
    },
    {
      "x": -18,
      "y": 4,
      "z": -11,
      "name": "Wood_Deadwood_Beam",
      "rotation": 3
    },
    {
      "x": -18,
      "y": 5,
      "z": -11,
      "name": "Wood_Deadwood_Beam",
      "rotation": 3
    },
    {
      "x": -18,
      "y": 0,
      "z": -10,
      "name": "Empty"
    },
    {
      "x": -18,
      "y": 1,
      "z": -10,
      "name": "Rock_Volcanic_Brick",
      "rotation": 3
    },
    {
      "x": -18,
      "y": 2,
      "z": -10,
      "name": "Rock_Volcanic_Brick",
      "rotation": 3
    },
    {
      "x": -18,
      "y": 3,
      "z": -10,
      "name": "Rock_Volcanic_Brick",
      "rotation": 3
    },
    {
      "x": -18,
      "y": 4,
      "z": -10,
      "name": "Rock_Volcanic_Brick",
      "rotation": 3
    },
    {
      "x": -18,
      "y": 5,
      "z": -10,
      "name": "Rock_Volcanic_Brick_Stairs",
      "rotation": 3
    },
    {
      "x": -18,
      "y": 0,
      "z": -9,
      "name": "Empty"
    },
    {
      "x": -18,
      "y": 1,
      "z": -9,
      "name": "Rock_Volcanic_Brick_Wall",
      "rotation": 3
    },
    {
      "x": -18,
      "y": 2,
      "z": -9,
      "name": "Rock_Volcanic_Brick_Wall",
      "rotation": 3
    },
    {
      "x": -18,
      "y": 3,
      "z": -9,
      "name": "Rock_Volcanic_Cobble_Beam",
      "rotation": 3
    },
    {
      "x": -18,
      "y": 4,
      "z": -9,
      "name": "Rock_Volcanic_Brick_Beam",
      "rotation": 3
    },
    {
      "x": -18,
      "y": 5,
      "z": -9,
      "name": "Wood_Deadwood_Beam",
      "rotation": 3
    },
    {
      "x": -18,
      "y": 6,
      "z": -9,
      "name": "Wood_Deadwood_Beam",
      "rotation": 3
    },
    {
      "x": -18,
      "y": 7,
      "z": -9,
      "name": "Wood_Deadwood_Beam",
      "rotation": 3
    },
    {
      "x": -18,
      "y": 0,
      "z": -8,
      "name": "Empty"
    },
    {
      "x": -18,
      "y": 1,
      "z": -8,
      "name": "Rock_Volcanic_Brick",
      "rotation": 3
    },
    {
      "x": -18,
      "y": 2,
      "z": -8,
      "name": "Rock_Volcanic_Brick",
      "rotation": 3
    },
    {
      "x": -18,
      "y": 3,
      "z": -8,
      "name": "Rock_Volcanic_Brick",
      "rotation": 3
    },
    {
      "x": -18,
      "y": 4,
      "z": -8,
      "name": "Rock_Volcanic_Brick",
      "rotation": 3
    },
    {
      "x": -18,
      "y": 5,
      "z": -8,
      "name": "Rock_Volcanic_Brick_Stairs",
      "rotation": 3
    },
    {
      "x": -18,
      "y": 0,
      "z": -7,
      "name": "Empty"
    },
    {
      "x": -18,
      "y": 1,
      "z": -7,
      "name": "Rock_Volcanic_Brick_Wall",
      "rotation": 3
    },
    {
      "x": -18,
      "y": 2,
      "z": -7,
      "name": "Rock_Volcanic_Cobble_Beam",
      "rotation": 3
    },
    {
      "x": -18,
      "y": 3,
      "z": -7,
      "name": "Rock_Volcanic_Brick_Beam",
      "rotation": 3
    },
    {
      "x": -18,
      "y": 4,
      "z": -7,
      "name": "Wood_Deadwood_Beam",
      "rotation": 3
    },
    {
      "x": -18,
      "y": 5,
      "z": -7,
      "name": "Wood_Deadwood_Beam",
      "rotation": 3
    },
    {
      "x": -18,
      "y": 0,
      "z": -6,
      "name": "Empty"
    },
    {
      "x": -18,
      "y": 1,
      "z": -6,
      "name": "Rock_Volcanic_Brick",
      "rotation": 3
    },
    {
      "x": -18,
      "y": 2,
      "z": -6,
      "name": "Rock_Volcanic_Brick",
      "rotation": 3
    },
    {
      "x": -18,
      "y": 3,
      "z": -6,
      "name": "Rock_Volcanic_Brick",
      "rotation": 3
    },
    {
      "x": -18,
      "y": 4,
      "z": -6,
      "name": "Rock_Volcanic_Brick_Stairs",
      "rotation": 3
    },
    {
      "x": -18,
      "y": 0,
      "z": -5,
      "name": "Empty"
    },
    {
      "x": -18,
      "y": 0,
      "z": -4,
      "name": "Empty"
    },
    {
      "x": -18,
      "y": 0,
      "z": -3,
      "name": "Empty"
    },
    {
      "x": -18,
      "y": 1,
      "z": -3,
      "name": "Rock_Volcanic_Brick",
      "rotation": 3
    },
    {
      "x": -18,
      "y": 2,
      "z": -3,
      "name": "Rock_Volcanic_Brick",
      "rotation": 3
    },
    {
      "x": -18,
      "y": 3,
      "z": -3,
      "name": "Rock_Volcanic_Brick",
      "rotation": 3
    },
    {
      "x": -18,
      "y": 4,
      "z": -3,
      "name": "Rock_Volcanic_Brick",
      "rotation": 3
    },
    {
      "x": -18,
      "y": 5,
      "z": -3,
      "name": "Rock_Volcanic_Brick_Stairs",
      "rotation": 3
    },
    {
      "x": -18,
      "y": 0,
      "z": -2,
      "name": "Empty"
    },
    {
      "x": -18,
      "y": 1,
      "z": -2,
      "name": "Rock_Volcanic_Brick_Wall",
      "rotation": 3
    },
    {
      "x": -18,
      "y": 2,
      "z": -2,
      "name": "Rock_Volcanic_Cobble_Beam",
      "rotation": 3
    },
    {
      "x": -18,
      "y": 3,
      "z": -2,
      "name": "Rock_Volcanic_Brick_Beam",
      "rotation": 3
    },
    {
      "x": -18,
      "y": 4,
      "z": -2,
      "name": "Wood_Deadwood_Beam",
      "rotation": 3
    },
    {
      "x": -18,
      "y": 5,
      "z": -2,
      "name": "Wood_Deadwood_Beam",
      "rotation": 3
    },
    {
      "x": -18,
      "y": 0,
      "z": -1,
      "name": "Empty"
    },
    {
      "x": -18,
      "y": 1,
      "z": -1,
      "name": "Rock_Volcanic_Brick",
      "rotation": 3
    },
    {
      "x": -18,
      "y": 2,
      "z": -1,
      "name": "Rock_Volcanic_Brick",
      "rotation": 3
    },
    {
      "x": -18,
      "y": 3,
      "z": -1,
      "name": "Rock_Volcanic_Brick",
      "rotation": 3
    },
    {
      "x": -18,
      "y": 4,
      "z": -1,
      "name": "Rock_Volcanic_Brick_Stairs",
      "rotation": 3
    },
    {
      "x": -18,
      "y": 0,
      "z": 0,
      "name": "Empty"
    },
    {
      "x": -18,
      "y": 0,
      "z": 1,
      "name": "Empty"
    },
    {
      "x": -18,
      "y": 0,
      "z": 2,
      "name": "Empty"
    },
    {
      "x": -18,
      "y": 1,
      "z": 2,
      "name": "Rock_Volcanic_Brick",
      "rotation": 3
    },
    {
      "x": -18,
      "y": 2,
      "z": 2,
      "name": "Rock_Volcanic_Brick",
      "rotation": 3
    },
    {
      "x": -18,
      "y": 3,
      "z": 2,
      "name": "Rock_Volcanic_Brick",
      "rotation": 3
    },
    {
      "x": -18,
      "y": 4,
      "z": 2,
      "name": "Rock_Volcanic_Brick",
      "rotation": 3
    },
    {
      "x": -18,
      "y": 5,
      "z": 2,
      "name": "Rock_Volcanic_Brick_Stairs",
      "rotation": 3
    },
    {
      "x": -18,
      "y": 0,
      "z": 3,
      "name": "Empty"
    },
    {
      "x": -18,
      "y": 1,
      "z": 3,
      "name": "Rock_Volcanic_Brick_Wall",
      "rotation": 3
    },
    {
      "x": -18,
      "y": 2,
      "z": 3,
      "name": "Rock_Volcanic_Cobble_Beam",
      "rotation": 3
    },
    {
      "x": -18,
      "y": 3,
      "z": 3,
      "name": "Rock_Volcanic_Brick_Beam",
      "rotation": 3
    },
    {
      "x": -18,
      "y": 4,
      "z": 3,
      "name": "Wood_Deadwood_Beam",
      "rotation": 3
    },
    {
      "x": -18,
      "y": 5,
      "z": 3,
      "name": "Wood_Deadwood_Beam",
      "rotation": 3
    },
    {
      "x": -18,
      "y": 0,
      "z": 4,
      "name": "Empty"
    },
    {
      "x": -18,
      "y": 1,
      "z": 4,
      "name": "Rock_Volcanic_Brick",
      "rotation": 3
    },
    {
      "x": -18,
      "y": 2,
      "z": 4,
      "name": "Rock_Volcanic_Brick",
      "rotation": 3
    },
    {
      "x": -18,
      "y": 3,
      "z": 4,
      "name": "Rock_Volcanic_Brick",
      "rotation": 3
    },
    {
      "x": -18,
      "y": 4,
      "z": 4,
      "name": "Rock_Volcanic_Brick_Stairs",
      "rotation": 3
    },
    {
      "x": -18,
      "y": 0,
      "z": 5,
      "name": "Empty"
    },
    {
      "x": -18,
      "y": 0,
      "z": 6,
      "name": "Empty"
    },
    {
      "x": -18,
      "y": 0,
      "z": 7,
      "name": "Empty"
    },
    {
      "x": -18,
      "y": 1,
      "z": 7,
      "name": "Rock_Volcanic_Brick",
      "rotation": 3
    },
    {
      "x": -18,
      "y": 2,
      "z": 7,
      "name": "Rock_Volcanic_Brick",
      "rotation": 3
    },
    {
      "x": -18,
      "y": 3,
      "z": 7,
      "name": "Rock_Volcanic_Brick",
      "rotation": 3
    },
    {
      "x": -18,
      "y": 4,
      "z": 7,
      "name": "Rock_Volcanic_Brick",
      "rotation": 3
    },
    {
      "x": -18,
      "y": 5,
      "z": 7,
      "name": "Rock_Volcanic_Brick_Stairs",
      "rotation": 3
    },
    {
      "x": -18,
      "y": 0,
      "z": 8,
      "name": "Empty"
    },
    {
      "x": -18,
      "y": 1,
      "z": 8,
      "name": "Rock_Volcanic_Brick_Wall",
      "rotation": 3
    },
    {
      "x": -18,
      "y": 2,
      "z": 8,
      "name": "Rock_Volcanic_Cobble_Beam",
      "rotation": 3
    },
    {
      "x": -18,
      "y": 3,
      "z": 8,
      "name": "Rock_Volcanic_Brick_Beam",
      "rotation": 3
    },
    {
      "x": -18,
      "y": 4,
      "z": 8,
      "name": "Wood_Deadwood_Beam",
      "rotation": 3
    },
    {
      "x": -18,
      "y": 5,
      "z": 8,
      "name": "Wood_Deadwood_Beam",
      "rotation": 3
    },
    {
      "x": -18,
      "y": 0,
      "z": 9,
      "name": "Empty"
    },
    {
      "x": -18,
      "y": 1,
      "z": 9,
      "name": "Rock_Volcanic_Brick",
      "rotation": 3
    },
    {
      "x": -18,
      "y": 2,
      "z": 9,
      "name": "Rock_Volcanic_Brick",
      "rotation": 3
    },
    {
      "x": -18,
      "y": 3,
      "z": 9,
      "name": "Rock_Volcanic_Brick",
      "rotation": 3
    },
    {
      "x": -18,
      "y": 4,
      "z": 9,
      "name": "Rock_Volcanic_Brick_Stairs",
      "rotation": 3
    },
    {
      "x": -18,
      "y": 0,
      "z": 10,
      "name": "Empty"
    },
    {
      "x": -18,
      "y": 0,
      "z": 11,
      "name": "Empty"
    },
    {
      "x": -18,
      "y": 0,
      "z": 12,
      "name": "Empty"
    },
    {
      "x": -18,
      "y": 0,
      "z": 13,
      "name": "Empty"
    },
    {
      "x": -18,
      "y": 0,
      "z": 14,
      "name": "Empty"
    },
    {
      "x": -18,
      "y": 1,
      "z": 14,
      "name": "Rock_Volcanic_Brick",
      "rotation": 3
    },
    {
      "x": -18,
      "y": 2,
      "z": 14,
      "name": "Rock_Volcanic_Brick",
      "rotation": 3
    },
    {
      "x": -18,
      "y": 3,
      "z": 14,
      "name": "Rock_Volcanic_Brick",
      "rotation": 3
    },
    {
      "x": -18,
      "y": 4,
      "z": 14,
      "name": "Rock_Volcanic_Brick_Stairs",
      "rotation": 3
    },
    {
      "x": -18,
      "y": 0,
      "z": 15,
      "name": "Empty"
    },
    {
      "x": -18,
      "y": 1,
      "z": 15,
      "name": "Rock_Volcanic_Brick_Wall",
      "rotation": 3
    },
    {
      "x": -18,
      "y": 2,
      "z": 15,
      "name": "Rock_Volcanic_Cobble_Beam",
      "rotation": 3
    },
    {
      "x": -18,
      "y": 3,
      "z": 15,
      "name": "Rock_Volcanic_Brick_Beam",
      "rotation": 3
    },
    {
      "x": -18,
      "y": 4,
      "z": 15,
      "name": "Wood_Deadwood_Beam",
      "rotation": 3
    },
    {
      "x": -18,
      "y": 5,
      "z": 15,
      "name": "Wood_Deadwood_Beam",
      "rotation": 3
    },
    {
      "x": -18,
      "y": 0,
      "z": 16,
      "name": "Empty"
    },
    {
      "x": -18,
      "y": 1,
      "z": 16,
      "name": "Rock_Volcanic_Brick",
      "rotation": 3
    },
    {
      "x": -18,
      "y": 2,
      "z": 16,
      "name": "Rock_Volcanic_Brick",
      "rotation": 3
    },
    {
      "x": -18,
      "y": 3,
      "z": 16,
      "name": "Rock_Volcanic_Brick",
      "rotation": 3
    },
    {
      "x": -18,
      "y": 4,
      "z": 16,
      "name": "Rock_Volcanic_Brick",
      "rotation": 3
    },
    {
      "x": -18,
      "y": 5,
      "z": 16,
      "name": "Rock_Volcanic_Brick_Stairs",
      "rotation": 3
    },
    {
      "x": -18,
      "y": 0,
      "z": 17,
      "name": "Empty"
    },
    {
      "x": -18,
      "y": 1,
      "z": 17,
      "name": "Rock_Volcanic_Brick_Wall",
      "rotation": 3
    },
    {
      "x": -18,
      "y": 2,
      "z": 17,
      "name": "Rock_Volcanic_Brick_Wall",
      "rotation": 3
    },
    {
      "x": -18,
      "y": 3,
      "z": 17,
      "name": "Rock_Volcanic_Cobble_Beam",
      "rotation": 3
    },
    {
      "x": -18,
      "y": 4,
      "z": 17,
      "name": "Rock_Volcanic_Brick_Beam",
      "rotation": 3
    },
    {
      "x": -18,
      "y": 5,
      "z": 17,
      "name": "Wood_Deadwood_Beam",
      "rotation": 3
    },
    {
      "x": -18,
      "y": 6,
      "z": 17,
      "name": "Wood_Deadwood_Beam",
      "rotation": 3
    },
    {
      "x": -18,
      "y": 7,
      "z": 17,
      "name": "Wood_Deadwood_Beam",
      "rotation": 3
    },
    {
      "x": -18,
      "y": 0,
      "z": 18,
      "name": "Empty"
    },
    {
      "x": -18,
      "y": 1,
      "z": 18,
      "name": "Rock_Volcanic_Brick",
      "rotation": 3
    },
    {
      "x": -18,
      "y": 2,
      "z": 18,
      "name": "Rock_Volcanic_Brick",
      "rotation": 3
    },
    {
      "x": -18,
      "y": 3,
      "z": 18,
      "name": "Rock_Volcanic_Brick",
      "rotation": 3
    },
    {
      "x": -18,
      "y": 4,
      "z": 18,
      "name": "Rock_Volcanic_Brick",
      "rotation": 3
    },
    {
      "x": -18,
      "y": 5,
      "z": 18,
      "name": "Rock_Volcanic_Brick_Stairs",
      "rotation": 3
    },
    {
      "x": -18,
      "y": 0,
      "z": 19,
      "name": "Empty"
    },
    {
      "x": -18,
      "y": 1,
      "z": 19,
      "name": "Rock_Volcanic_Brick_Wall",
      "rotation": 3
    },
    {
      "x": -18,
      "y": 2,
      "z": 19,
      "name": "Rock_Volcanic_Cobble_Beam",
      "rotation": 3
    },
    {
      "x": -18,
      "y": 3,
      "z": 19,
      "name": "Rock_Volcanic_Brick_Beam",
      "rotation": 3
    },
    {
      "x": -18,
      "y": 4,
      "z": 19,
      "name": "Wood_Deadwood_Beam",
      "rotation": 3
    },
    {
      "x": -18,
      "y": 5,
      "z": 19,
      "name": "Wood_Deadwood_Beam",
      "rotation": 3
    },
    {
      "x": -18,
      "y": 0,
      "z": 20,
      "name": "Empty"
    },
    {
      "x": -18,
      "y": 1,
      "z": 20,
      "name": "Rock_Volcanic_Brick",
      "rotation": 3
    },
    {
      "x": -18,
      "y": 2,
      "z": 20,
      "name": "Rock_Volcanic_Brick",
      "rotation": 3
    },
    {
      "x": -18,
      "y": 3,
      "z": 20,
      "name": "Rock_Volcanic_Brick",
      "rotation": 3
    },
    {
      "x": -18,
      "y": 4,
      "z": 20,
      "name": "Rock_Volcanic_Brick_Stairs",
      "rotation": 3
    },
    {
      "x": -18,
      "y": 0,
      "z": 21,
      "name": "Empty"
    },
    {
      "x": -18,
      "y": 0,
      "z": 22,
      "name": "Empty"
    },
    {
      "x": -18,
      "y": 0,
      "z": 23,
      "name": "Empty"
    },
    {
      "x": -17,
      "y": 0,
      "z": -22,
      "name": "Empty"
    },
    {
      "x": -17,
      "y": 0,
      "z": -21,
      "name": "Empty"
    },
    {
      "x": -17,
      "y": 0,
      "z": -20,
      "name": "Empty"
    },
    {
      "x": -17,
      "y": 0,
      "z": -19,
      "name": "Empty"
    },
    {
      "x": -17,
      "y": 0,
      "z": -18,
      "name": "Empty"
    },
    {
      "x": -17,
      "y": 0,
      "z": -17,
      "name": "Empty"
    },
    {
      "x": -17,
      "y": 0,
      "z": -16,
      "name": "Empty"
    },
    {
      "x": -17,
      "y": 0,
      "z": -15,
      "name": "Empty"
    },
    {
      "x": -17,
      "y": 0,
      "z": -14,
      "name": "Empty"
    },
    {
      "x": -17,
      "y": 0,
      "z": -13,
      "name": "Empty"
    },
    {
      "x": -17,
      "y": 1,
      "z": -13,
      "name": "Rock_Volcanic_Brick",
      "rotation": 2
    },
    {
      "x": -17,
      "y": 2,
      "z": -13,
      "name": "Rock_Volcanic_Brick",
      "rotation": 2
    },
    {
      "x": -17,
      "y": 3,
      "z": -13,
      "name": "Rock_Volcanic_Brick",
      "rotation": 2
    },
    {
      "x": -17,
      "y": 4,
      "z": -13,
      "name": "Rock_Volcanic_Brick_Stairs",
      "rotation": 2
    },
    {
      "x": -17,
      "y": 0,
      "z": -12,
      "name": "Empty"
    },
    {
      "x": -17,
      "y": 1,
      "z": -12,
      "name": "Rock_Volcanic_Brick",
      "rotation": 2
    },
    {
      "x": -17,
      "y": 2,
      "z": -12,
      "name": "Rock_Volcanic_Brick",
      "rotation": 2
    },
    {
      "x": -17,
      "y": 3,
      "z": -12,
      "name": "Rock_Volcanic_Brick",
      "rotation": 2
    },
    {
      "x": -17,
      "y": 4,
      "z": -12,
      "name": "Rock_Volcanic_Brick",
      "rotation": 2
    },
    {
      "x": -17,
      "y": 5,
      "z": -12,
      "name": "Rock_Volcanic_Brick",
      "rotation": 2
    },
    {
      "x": -17,
      "y": 6,
      "z": -12,
      "name": "Rock_Volcanic_Brick",
      "rotation": 2
    },
    {
      "x": -17,
      "y": 7,
      "z": -12,
      "name": "Rock_Volcanic_Brick",
      "rotation": 2
    },
    {
      "x": -17,
      "y": 8,
      "z": -12,
      "name": "Rock_Volcanic_Brick",
      "rotation": 2
    },
    {
      "x": -17,
      "y": 9,
      "z": -12,
      "name": "Rock_Volcanic_Brick",
      "rotation": 2
    },
    {
      "x": -17,
      "y": 10,
      "z": -12,
      "name": "Rock_Volcanic_Brick",
      "rotation": 2
    },
    {
      "x": -17,
      "y": 11,
      "z": -12,
      "name": "Rock_Volcanic_Brick",
      "rotation": 2
    },
    {
      "x": -17,
      "y": 12,
      "z": -12,
      "name": "Rock_Volcanic_Brick",
      "rotation": 2
    },
    {
      "x": -17,
      "y": 13,
      "z": -12,
      "name": "Rock_Volcanic_Brick",
      "rotation": 2
    },
    {
      "x": -17,
      "y": 14,
      "z": -12,
      "name": "Rock_Volcanic_Brick_Stairs",
      "rotation": 11
    },
    {
      "x": -17,
      "y": 0,
      "z": -11,
      "name": "Empty"
    },
    {
      "x": -17,
      "y": 1,
      "z": -11,
      "name": "Rock_Volcanic_Brick",
      "rotation": 3
    },
    {
      "x": -17,
      "y": 2,
      "z": -11,
      "name": "Rock_Volcanic_Brick",
      "rotation": 3
    },
    {
      "x": -17,
      "y": 3,
      "z": -11,
      "name": "Rock_Volcanic_Brick",
      "rotation": 3
    },
    {
      "x": -17,
      "y": 4,
      "z": -11,
      "name": "Rock_Volcanic_Brick",
      "rotation": 3
    },
    {
      "x": -17,
      "y": 12,
      "z": -11,
      "name": "Rock_Volcanic_Brick_Stairs",
      "rotation": 9
    },
    {
      "x": -17,
      "y": 13,
      "z": -11,
      "name": "Rock_Volcanic_Brick_Stairs",
      "rotation": 3
    },
    {
      "x": -17,
      "y": 14,
      "z": -11,
      "name": "Rock_Volcanic_Brick_Ornate",
      "rotation": 3
    },
    {
      "x": -17,
      "y": 0,
      "z": -10,
      "name": "Empty"
    },
    {
      "x": -17,
      "y": 1,
      "z": -10,
      "name": "Rock_Volcanic_Brick",
      "rotation": 3
    },
    {
      "x": -17,
      "y": 2,
      "z": -10,
      "name": "Rock_Volcanic_Brick",
      "rotation": 3
    },
    {
      "x": -17,
      "y": 3,
      "z": -10,
      "name": "Rock_Volcanic_Brick",
      "rotation": 3
    },
    {
      "x": -17,
      "y": 4,
      "z": -10,
      "name": "Rock_Volcanic_Brick",
      "rotation": 3
    },
    {
      "x": -17,
      "y": 5,
      "z": -10,
      "name": "Rock_Volcanic_Brick",
      "rotation": 3
    },
    {
      "x": -17,
      "y": 6,
      "z": -10,
      "name": "Rock_Volcanic_Brick",
      "rotation": 3
    },
    {
      "x": -17,
      "y": 7,
      "z": -10,
      "name": "Rock_Volcanic_Brick",
      "rotation": 3
    },
    {
      "x": -17,
      "y": 8,
      "z": -10,
      "name": "Rock_Volcanic_Brick",
      "rotation": 3
    },
    {
      "x": -17,
      "y": 9,
      "z": -10,
      "name": "Rock_Volcanic_Brick",
      "rotation": 3
    },
    {
      "x": -17,
      "y": 10,
      "z": -10,
      "name": "Rock_Volcanic_Brick",
      "rotation": 3
    },
    {
      "x": -17,
      "y": 11,
      "z": -10,
      "name": "Rock_Volcanic_Brick",
      "rotation": 3
    },
    {
      "x": -17,
      "y": 12,
      "z": -10,
      "name": "Rock_Volcanic_Brick",
      "rotation": 3
    },
    {
      "x": -17,
      "y": 13,
      "z": -10,
      "name": "Rock_Volcanic_Brick",
      "rotation": 3
    },
    {
      "x": -17,
      "y": 14,
      "z": -10,
      "name": "Rock_Volcanic_Brick",
      "rotation": 3
    },
    {
      "x": -17,
      "y": 15,
      "z": -10,
      "name": "Rock_Volcanic_Brick_Stairs",
      "rotation": 8
    },
    {
      "x": -17,
      "y": 0,
      "z": -9,
      "name": "Empty"
    },
    {
      "x": -17,
      "y": 1,
      "z": -9,
      "name": "Rock_Volcanic_Brick",
      "rotation": 3
    },
    {
      "x": -17,
      "y": 2,
      "z": -9,
      "name": "Rock_Volcanic_Brick",
      "rotation": 3
    },
    {
      "x": -17,
      "y": 3,
      "z": -9,
      "name": "Rock_Volcanic_Brick",
      "rotation": 3
    },
    {
      "x": -17,
      "y": 4,
      "z": -9,
      "name": "Rock_Volcanic_Brick",
      "rotation": 3
    },
    {
      "x": -17,
      "y": 13,
      "z": -9,
      "name": "Rock_Volcanic_Brick_Stairs",
      "rotation": 9
    },
    {
      "x": -17,
      "y": 14,
      "z": -9,
      "name": "Rock_Volcanic_Brick_Stairs",
      "rotation": 3
    },
    {
      "x": -17,
      "y": 15,
      "z": -9,
      "name": "Rock_Volcanic_Brick_Ornate",
      "rotation": 3
    },
    {
      "x": -17,
      "y": 16,
      "z": -9,
      "name": "Rock_Volcanic_Brick_Stairs",
      "rotation": 8
    },
    {
      "x": -17,
      "y": 17,
      "z": -9,
      "name": "Rock_Crystal_Purple_Small",
      "rotation": 7
    },
    {
      "x": -17,
      "y": 0,
      "z": -8,
      "name": "Empty"
    },
    {
      "x": -17,
      "y": 1,
      "z": -8,
      "name": "Rock_Volcanic_Brick",
      "rotation": 3
    },
    {
      "x": -17,
      "y": 2,
      "z": -8,
      "name": "Rock_Volcanic_Brick",
      "rotation": 3
    },
    {
      "x": -17,
      "y": 3,
      "z": -8,
      "name": "Rock_Volcanic_Brick",
      "rotation": 3
    },
    {
      "x": -17,
      "y": 4,
      "z": -8,
      "name": "Rock_Volcanic_Brick",
      "rotation": 3
    },
    {
      "x": -17,
      "y": 5,
      "z": -8,
      "name": "Rock_Volcanic_Brick",
      "rotation": 3
    },
    {
      "x": -17,
      "y": 6,
      "z": -8,
      "name": "Rock_Volcanic_Brick",
      "rotation": 3
    },
    {
      "x": -17,
      "y": 7,
      "z": -8,
      "name": "Rock_Volcanic_Brick",
      "rotation": 3
    },
    {
      "x": -17,
      "y": 8,
      "z": -8,
      "name": "Rock_Volcanic_Brick",
      "rotation": 3
    },
    {
      "x": -17,
      "y": 9,
      "z": -8,
      "name": "Rock_Volcanic_Brick",
      "rotation": 3
    },
    {
      "x": -17,
      "y": 10,
      "z": -8,
      "name": "Rock_Volcanic_Brick",
      "rotation": 3
    },
    {
      "x": -17,
      "y": 11,
      "z": -8,
      "name": "Rock_Volcanic_Brick",
      "rotation": 3
    },
    {
      "x": -17,
      "y": 12,
      "z": -8,
      "name": "Rock_Volcanic_Brick",
      "rotation": 3
    },
    {
      "x": -17,
      "y": 13,
      "z": -8,
      "name": "Rock_Volcanic_Brick",
      "rotation": 3
    },
    {
      "x": -17,
      "y": 14,
      "z": -8,
      "name": "Rock_Volcanic_Brick",
      "rotation": 3
    },
    {
      "x": -17,
      "y": 15,
      "z": -8,
      "name": "Rock_Volcanic_Brick",
      "rotation": 3
    },
    {
      "x": -17,
      "y": 16,
      "z": -8,
      "name": "Rock_Volcanic_Brick",
      "rotation": 3
    },
    {
      "x": -17,
      "y": 17,
      "z": -8,
      "name": "Rock_Volcanic_Brick_Stairs",
      "rotation": 8
    },
    {
      "x": -17,
      "y": 0,
      "z": -7,
      "name": "Empty"
    },
    {
      "x": -17,
      "y": 1,
      "z": -7,
      "name": "Rock_Volcanic_Brick",
      "rotation": 3
    },
    {
      "x": -17,
      "y": 2,
      "z": -7,
      "name": "Rock_Volcanic_Brick",
      "rotation": 3
    },
    {
      "x": -17,
      "y": 3,
      "z": -7,
      "name": "Rock_Volcanic_Brick",
      "rotation": 3
    },
    {
      "x": -17,
      "y": 4,
      "z": -7,
      "name": "Rock_Volcanic_Brick",
      "rotation": 3
    },
    {
      "x": -17,
      "y": 7,
      "z": -7,
      "name": "Rock_Crystal_Purple_Small",
      "rotation": 7
    },
    {
      "x": -17,
      "y": 8,
      "z": -7,
      "name": "Rock_Crystal_Purple_Large",
      "rotation": 7
    },
    {
      "x": -17,
      "y": 9,
      "z": -7,
      "name": "Rock_Crystal_Purple_Small",
      "rotation": 7
    },
    {
      "x": -17,
      "y": 13,
      "z": -7,
      "name": "Rock_Volcanic_Brick_Stairs",
      "rotation": 9
    },
    {
      "x": -17,
      "y": 14,
      "z": -7,
      "name": "Rock_Volcanic_Brick_Ornate",
      "rotation": 3
    },
    {
      "x": -17,
      "y": 15,
      "z": -7,
      "name": "Rock_Volcanic_Brick_Stairs",
      "rotation": 3
    },
    {
      "x": -17,
      "y": 16,
      "z": -7,
      "name": "Rock_Volcanic_Brick_Stairs",
      "rotation": 9
    },
    {
      "x": -17,
      "y": 17,
      "z": -7,
      "name": "Rock_Volcanic_Brick_Ornate",
      "rotation": 3
    },
    {
      "x": -17,
      "y": 0,
      "z": -6,
      "name": "Empty"
    },
    {
      "x": -17,
      "y": 1,
      "z": -6,
      "name": "Rock_Volcanic_Brick",
      "rotation": 3
    },
    {
      "x": -17,
      "y": 2,
      "z": -6,
      "name": "Rock_Volcanic_Brick",
      "rotation": 3
    },
    {
      "x": -17,
      "y": 3,
      "z": -6,
      "name": "Rock_Volcanic_Brick",
      "rotation": 3
    },
    {
      "x": -17,
      "y": 4,
      "z": -6,
      "name": "Rock_Volcanic_Brick",
      "rotation": 3
    },
    {
      "x": -17,
      "y": 5,
      "z": -6,
      "name": "Rock_Volcanic_Brick",
      "rotation": 3
    },
    {
      "x": -17,
      "y": 6,
      "z": -6,
      "name": "Rock_Volcanic_Brick",
      "rotation": 3
    },
    {
      "x": -17,
      "y": 7,
      "z": -6,
      "name": "Rock_Volcanic_Brick",
      "rotation": 3
    },
    {
      "x": -17,
      "y": 8,
      "z": -6,
      "name": "Rock_Volcanic_Brick",
      "rotation": 3
    },
    {
      "x": -17,
      "y": 9,
      "z": -6,
      "name": "Rock_Volcanic_Brick",
      "rotation": 3
    },
    {
      "x": -17,
      "y": 10,
      "z": -6,
      "name": "Rock_Volcanic_Brick",
      "rotation": 3
    },
    {
      "x": -17,
      "y": 11,
      "z": -6,
      "name": "Rock_Volcanic_Brick",
      "rotation": 3
    },
    {
      "x": -17,
      "y": 12,
      "z": -6,
      "name": "Rock_Volcanic_Brick",
      "rotation": 3
    },
    {
      "x": -17,
      "y": 13,
      "z": -6,
      "name": "Rock_Volcanic_Brick",
      "rotation": 3
    },
    {
      "x": -17,
      "y": 14,
      "z": -6,
      "name": "Rock_Volcanic_Brick",
      "rotation": 3
    },
    {
      "x": -17,
      "y": 15,
      "z": -6,
      "name": "Rock_Volcanic_Brick",
      "rotation": 3
    },
    {
      "x": -17,
      "y": 16,
      "z": -6,
      "name": "Rock_Volcanic_Brick",
      "rotation": 3
    },
    {
      "x": -17,
      "y": 17,
      "z": -6,
      "name": "Rock_Volcanic_Brick_Stairs",
      "rotation": 10
    },
    {
      "x": -17,
      "y": 18,
      "z": -6,
      "name": "Rock_Volcanic_Brick",
      "rotation": 3
    },
    {
      "x": -17,
      "y": 19,
      "z": -6,
      "name": "Rock_Volcanic_Brick",
      "rotation": 3
    },
    {
      "x": -17,
      "y": 0,
      "z": -5,
      "name": "Empty"
    },
    {
      "x": -17,
      "y": 1,
      "z": -5,
      "name": "Rock_Volcanic_Brick",
      "rotation": 3
    },
    {
      "x": -17,
      "y": 2,
      "z": -5,
      "name": "Rock_Volcanic_Brick",
      "rotation": 3
    },
    {
      "x": -17,
      "y": 3,
      "z": -5,
      "name": "Rock_Volcanic_Brick",
      "rotation": 3
    },
    {
      "x": -17,
      "y": 4,
      "z": -5,
      "name": "Rock_Volcanic_Brick_Stairs"
    },
    {
      "x": -17,
      "y": 13,
      "z": -5,
      "name": "Rock_Volcanic_Brick_Stairs",
      "rotation": 10
    },
    {
      "x": -17,
      "y": 14,
      "z": -5,
      "name": "Rock_Volcanic_Brick_Stairs",
      "rotation": 3
    },
    {
      "x": -17,
      "y": 15,
      "z": -5,
      "name": "Rock_Volcanic_Brick_Ornate",
      "rotation": 1
    },
    {
      "x": -17,
      "y": 0,
      "z": -4,
      "name": "Rock_Basalt_Brick_Stairs",
      "rotation": 3
    },
    {
      "x": -17,
      "y": 1,
      "z": -4,
      "name": "Rock_Volcanic_Brick",
      "rotation": 1
    },
    {
      "x": -17,
      "y": 2,
      "z": -4,
      "name": "Rock_Volcanic_Brick",
      "rotation": 1
    },
    {
      "x": -17,
      "y": 3,
      "z": -4,
      "name": "Rock_Volcanic_Brick",
      "rotation": 1
    },
    {
      "x": -17,
      "y": 4,
      "z": -4,
      "name": "Rock_Volcanic_Brick_Stairs",
      "rotation": 2
    },
    {
      "x": -17,
      "y": 13,
      "z": -4,
      "name": "Rock_Volcanic_Brick_Stairs",
      "rotation": 8
    },
    {
      "x": -17,
      "y": 14,
      "z": -4,
      "name": "Rock_Volcanic_Brick_Stairs",
      "rotation": 3
    },
    {
      "x": -17,
      "y": 15,
      "z": -4,
      "name": "Rock_Volcanic_Brick_Ornate",
      "rotation": 1
    },
    {
      "x": -17,
      "y": 0,
      "z": -3,
      "name": "Empty"
    },
    {
      "x": -17,
      "y": 1,
      "z": -3,
      "name": "Rock_Volcanic_Brick",
      "rotation": 3
    },
    {
      "x": -17,
      "y": 2,
      "z": -3,
      "name": "Rock_Volcanic_Brick",
      "rotation": 3
    },
    {
      "x": -17,
      "y": 3,
      "z": -3,
      "name": "Rock_Volcanic_Brick",
      "rotation": 3
    },
    {
      "x": -17,
      "y": 4,
      "z": -3,
      "name": "Rock_Volcanic_Brick",
      "rotation": 3
    },
    {
      "x": -17,
      "y": 5,
      "z": -3,
      "name": "Rock_Volcanic_Brick",
      "rotation": 3
    },
    {
      "x": -17,
      "y": 6,
      "z": -3,
      "name": "Rock_Volcanic_Brick",
      "rotation": 3
    },
    {
      "x": -17,
      "y": 7,
      "z": -3,
      "name": "Rock_Volcanic_Brick",
      "rotation": 3
    },
    {
      "x": -17,
      "y": 8,
      "z": -3,
      "name": "Rock_Volcanic_Brick",
      "rotation": 3
    },
    {
      "x": -17,
      "y": 9,
      "z": -3,
      "name": "Rock_Volcanic_Brick",
      "rotation": 3
    },
    {
      "x": -17,
      "y": 10,
      "z": -3,
      "name": "Rock_Volcanic_Brick",
      "rotation": 3
    },
    {
      "x": -17,
      "y": 11,
      "z": -3,
      "name": "Rock_Volcanic_Brick",
      "rotation": 3
    },
    {
      "x": -17,
      "y": 12,
      "z": -3,
      "name": "Rock_Volcanic_Brick",
      "rotation": 3
    },
    {
      "x": -17,
      "y": 13,
      "z": -3,
      "name": "Rock_Volcanic_Brick",
      "rotation": 3
    },
    {
      "x": -17,
      "y": 14,
      "z": -3,
      "name": "Rock_Volcanic_Brick",
      "rotation": 3
    },
    {
      "x": -17,
      "y": 15,
      "z": -3,
      "name": "Rock_Volcanic_Brick",
      "rotation": 3
    },
    {
      "x": -17,
      "y": 16,
      "z": -3,
      "name": "Rock_Volcanic_Brick",
      "rotation": 3
    },
    {
      "x": -17,
      "y": 17,
      "z": -3,
      "name": "Rock_Volcanic_Brick_Stairs",
      "rotation": 8
    },
    {
      "x": -17,
      "y": 18,
      "z": -3,
      "name": "Rock_Volcanic_Brick",
      "rotation": 1
    },
    {
      "x": -17,
      "y": 19,
      "z": -3,
      "name": "Rock_Volcanic_Brick_Stairs",
      "rotation": 2
    },
    {
      "x": -17,
      "y": 0,
      "z": -2,
      "name": "Empty"
    },
    {
      "x": -17,
      "y": 1,
      "z": -2,
      "name": "Rock_Volcanic_Brick",
      "rotation": 3
    },
    {
      "x": -17,
      "y": 2,
      "z": -2,
      "name": "Rock_Volcanic_Brick",
      "rotation": 3
    },
    {
      "x": -17,
      "y": 3,
      "z": -2,
      "name": "Rock_Volcanic_Brick",
      "rotation": 3
    },
    {
      "x": -17,
      "y": 4,
      "z": -2,
      "name": "Rock_Volcanic_Brick",
      "rotation": 3
    },
    {
      "x": -17,
      "y": 9,
      "z": -2,
      "name": "Rock_Crystal_Purple_Small",
      "rotation": 7
    },
    {
      "x": -17,
      "y": 10,
      "z": -2,
      "name": "Rock_Crystal_Purple_Large",
      "rotation": 7
    },
    {
      "x": -17,
      "y": 11,
      "z": -2,
      "name": "Rock_Crystal_Purple_Small",
      "rotation": 7
    },
    {
      "x": -17,
      "y": 13,
      "z": -2,
      "name": "Rock_Volcanic_Brick_Stairs",
      "rotation": 9
    },
    {
      "x": -17,
      "y": 14,
      "z": -2,
      "name": "Rock_Volcanic_Brick_Ornate",
      "rotation": 3
    },
    {
      "x": -17,
      "y": 15,
      "z": -2,
      "name": "Rock_Volcanic_Brick_Stairs",
      "rotation": 3
    },
    {
      "x": -17,
      "y": 16,
      "z": -2,
      "name": "Rock_Volcanic_Brick_Stairs",
      "rotation": 9
    },
    {
      "x": -17,
      "y": 17,
      "z": -2,
      "name": "Rock_Volcanic_Brick_Ornate",
      "rotation": 3
    },
    {
      "x": -17,
      "y": 18,
      "z": -2,
      "name": "Rock_Volcanic_Brick_Stairs",
      "rotation": 9
    },
    {
      "x": -17,
      "y": 19,
      "z": -2,
      "name": "Rock_Volcanic_Brick",
      "rotation": 1
    },
    {
      "x": -17,
      "y": 0,
      "z": -1,
      "name": "Empty"
    },
    {
      "x": -17,
      "y": 1,
      "z": -1,
      "name": "Rock_Volcanic_Brick",
      "rotation": 3
    },
    {
      "x": -17,
      "y": 2,
      "z": -1,
      "name": "Rock_Volcanic_Brick",
      "rotation": 3
    },
    {
      "x": -17,
      "y": 3,
      "z": -1,
      "name": "Rock_Volcanic_Brick",
      "rotation": 3
    },
    {
      "x": -17,
      "y": 4,
      "z": -1,
      "name": "Rock_Volcanic_Brick",
      "rotation": 3
    },
    {
      "x": -17,
      "y": 5,
      "z": -1,
      "name": "Rock_Volcanic_Brick",
      "rotation": 3
    },
    {
      "x": -17,
      "y": 6,
      "z": -1,
      "name": "Rock_Volcanic_Brick",
      "rotation": 3
    },
    {
      "x": -17,
      "y": 7,
      "z": -1,
      "name": "Rock_Volcanic_Brick",
      "rotation": 3
    },
    {
      "x": -17,
      "y": 8,
      "z": -1,
      "name": "Rock_Volcanic_Brick",
      "rotation": 3
    },
    {
      "x": -17,
      "y": 9,
      "z": -1,
      "name": "Rock_Volcanic_Brick",
      "rotation": 3
    },
    {
      "x": -17,
      "y": 10,
      "z": -1,
      "name": "Rock_Volcanic_Brick",
      "rotation": 3
    },
    {
      "x": -17,
      "y": 11,
      "z": -1,
      "name": "Rock_Volcanic_Brick",
      "rotation": 3
    },
    {
      "x": -17,
      "y": 12,
      "z": -1,
      "name": "Rock_Volcanic_Brick",
      "rotation": 3
    },
    {
      "x": -17,
      "y": 13,
      "z": -1,
      "name": "Rock_Volcanic_Brick",
      "rotation": 3
    },
    {
      "x": -17,
      "y": 14,
      "z": -1,
      "name": "Rock_Volcanic_Brick",
      "rotation": 3
    },
    {
      "x": -17,
      "y": 15,
      "z": -1,
      "name": "Rock_Volcanic_Brick",
      "rotation": 3
    },
    {
      "x": -17,
      "y": 16,
      "z": -1,
      "name": "Rock_Volcanic_Brick",
      "rotation": 3
    },
    {
      "x": -17,
      "y": 17,
      "z": -1,
      "name": "Rock_Volcanic_Brick_Stairs",
      "rotation": 10
    },
    {
      "x": -17,
      "y": 18,
      "z": -1,
      "name": "Rock_Volcanic_Brick",
      "rotation": 1
    },
    {
      "x": -17,
      "y": 19,
      "z": -1,
      "name": "Rock_Volcanic_Brick_Stairs"
    },
    {
      "x": -17,
      "y": 0,
      "z": 0,
      "name": "Empty"
    },
    {
      "x": -17,
      "y": 1,
      "z": 0,
      "name": "Rock_Volcanic_Brick",
      "rotation": 3
    },
    {
      "x": -17,
      "y": 2,
      "z": 0,
      "name": "Rock_Volcanic_Brick",
      "rotation": 3
    },
    {
      "x": -17,
      "y": 3,
      "z": 0,
      "name": "Rock_Volcanic_Brick",
      "rotation": 3
    },
    {
      "x": -17,
      "y": 4,
      "z": 0,
      "name": "Rock_Volcanic_Brick_Stairs"
    },
    {
      "x": -17,
      "y": 13,
      "z": 0,
      "name": "Rock_Volcanic_Brick_Stairs",
      "rotation": 10
    },
    {
      "x": -17,
      "y": 14,
      "z": 0,
      "name": "Rock_Volcanic_Brick_Stairs",
      "rotation": 3
    },
    {
      "x": -17,
      "y": 15,
      "z": 0,
      "name": "Rock_Volcanic_Brick_Ornate",
      "rotation": 1
    },
    {
      "x": -17,
      "y": 0,
      "z": 1,
      "name": "Rock_Basalt_Brick_Stairs",
      "rotation": 3
    },
    {
      "x": -17,
      "y": 1,
      "z": 1,
      "name": "Rock_Volcanic_Brick",
      "rotation": 1
    },
    {
      "x": -17,
      "y": 2,
      "z": 1,
      "name": "Rock_Volcanic_Brick",
      "rotation": 1
    },
    {
      "x": -17,
      "y": 3,
      "z": 1,
      "name": "Rock_Volcanic_Brick",
      "rotation": 1
    },
    {
      "x": -17,
      "y": 4,
      "z": 1,
      "name": "Rock_Volcanic_Brick_Stairs",
      "rotation": 2
    },
    {
      "x": -17,
      "y": 13,
      "z": 1,
      "name": "Rock_Volcanic_Brick_Stairs",
      "rotation": 8
    },
    {
      "x": -17,
      "y": 14,
      "z": 1,
      "name": "Rock_Volcanic_Brick_Stairs",
      "rotation": 3
    },
    {
      "x": -17,
      "y": 0,
      "z": 2,
      "name": "Empty"
    },
    {
      "x": -17,
      "y": 1,
      "z": 2,
      "name": "Rock_Volcanic_Brick",
      "rotation": 3
    },
    {
      "x": -17,
      "y": 2,
      "z": 2,
      "name": "Rock_Volcanic_Brick",
      "rotation": 3
    },
    {
      "x": -17,
      "y": 3,
      "z": 2,
      "name": "Rock_Volcanic_Brick",
      "rotation": 3
    },
    {
      "x": -17,
      "y": 4,
      "z": 2,
      "name": "Rock_Volcanic_Brick",
      "rotation": 3
    },
    {
      "x": -17,
      "y": 5,
      "z": 2,
      "name": "Rock_Volcanic_Brick",
      "rotation": 3
    },
    {
      "x": -17,
      "y": 6,
      "z": 2,
      "name": "Rock_Volcanic_Brick",
      "rotation": 3
    },
    {
      "x": -17,
      "y": 7,
      "z": 2,
      "name": "Rock_Volcanic_Brick",
      "rotation": 3
    },
    {
      "x": -17,
      "y": 8,
      "z": 2,
      "name": "Rock_Volcanic_Brick",
      "rotation": 3
    },
    {
      "x": -17,
      "y": 9,
      "z": 2,
      "name": "Rock_Volcanic_Brick",
      "rotation": 3
    },
    {
      "x": -17,
      "y": 10,
      "z": 2,
      "name": "Rock_Volcanic_Brick",
      "rotation": 3
    },
    {
      "x": -17,
      "y": 11,
      "z": 2,
      "name": "Rock_Volcanic_Brick",
      "rotation": 3
    },
    {
      "x": -17,
      "y": 12,
      "z": 2,
      "name": "Rock_Volcanic_Brick",
      "rotation": 3
    },
    {
      "x": -17,
      "y": 13,
      "z": 2,
      "name": "Rock_Volcanic_Brick",
      "rotation": 3
    },
    {
      "x": -17,
      "y": 14,
      "z": 2,
      "name": "Rock_Volcanic_Brick",
      "rotation": 3
    },
    {
      "x": -17,
      "y": 15,
      "z": 2,
      "name": "Rock_Volcanic_Brick",
      "rotation": 1
    },
    {
      "x": -17,
      "y": 16,
      "z": 2,
      "name": "Rock_Volcanic_Brick",
      "rotation": 3
    },
    {
      "x": -17,
      "y": 17,
      "z": 2,
      "name": "Rock_Volcanic_Brick_Stairs",
      "rotation": 8
    },
    {
      "x": -17,
      "y": 18,
      "z": 2,
      "name": "Rock_Volcanic_Brick",
      "rotation": 1
    },
    {
      "x": -17,
      "y": 19,
      "z": 2,
      "name": "Rock_Volcanic_Brick_Stairs",
      "rotation": 2
    },
    {
      "x": -17,
      "y": 0,
      "z": 3,
      "name": "Empty"
    },
    {
      "x": -17,
      "y": 1,
      "z": 3,
      "name": "Rock_Volcanic_Brick",
      "rotation": 3
    },
    {
      "x": -17,
      "y": 2,
      "z": 3,
      "name": "Rock_Volcanic_Brick",
      "rotation": 3
    },
    {
      "x": -17,
      "y": 3,
      "z": 3,
      "name": "Rock_Volcanic_Brick",
      "rotation": 3
    },
    {
      "x": -17,
      "y": 4,
      "z": 3,
      "name": "Rock_Volcanic_Brick",
      "rotation": 3
    },
    {
      "x": -17,
      "y": 7,
      "z": 3,
      "name": "Rock_Crystal_Purple_Large",
      "rotation": 7
    },
    {
      "x": -17,
      "y": 8,
      "z": 3,
      "name": "Rock_Crystal_Purple_Small",
      "rotation": 7
    },
    {
      "x": -17,
      "y": 11,
      "z": 3,
      "name": "Rock_Crystal_Purple_Small",
      "rotation": 7
    },
    {
      "x": -17,
      "y": 13,
      "z": 3,
      "name": "Rock_Volcanic_Brick_Stairs",
      "rotation": 9
    },
    {
      "x": -17,
      "y": 14,
      "z": 3,
      "name": "Rock_Volcanic_Brick_Ornate",
      "rotation": 3
    },
    {
      "x": -17,
      "y": 15,
      "z": 3,
      "name": "Rock_Volcanic_Brick_Stairs",
      "rotation": 3
    },
    {
      "x": -17,
      "y": 16,
      "z": 3,
      "name": "Rock_Volcanic_Brick_Stairs",
      "rotation": 9
    },
    {
      "x": -17,
      "y": 17,
      "z": 3,
      "name": "Rock_Volcanic_Brick_Ornate",
      "rotation": 3
    },
    {
      "x": -17,
      "y": 18,
      "z": 3,
      "name": "Rock_Volcanic_Brick_Stairs",
      "rotation": 3
    },
    {
      "x": -17,
      "y": 19,
      "z": 3,
      "name": "Rock_Volcanic_Brick",
      "rotation": 1
    },
    {
      "x": -17,
      "y": 0,
      "z": 4,
      "name": "Empty"
    },
    {
      "x": -17,
      "y": 1,
      "z": 4,
      "name": "Rock_Volcanic_Brick",
      "rotation": 3
    },
    {
      "x": -17,
      "y": 2,
      "z": 4,
      "name": "Rock_Volcanic_Brick",
      "rotation": 3
    },
    {
      "x": -17,
      "y": 3,
      "z": 4,
      "name": "Rock_Volcanic_Brick",
      "rotation": 3
    },
    {
      "x": -17,
      "y": 4,
      "z": 4,
      "name": "Rock_Volcanic_Brick",
      "rotation": 3
    },
    {
      "x": -17,
      "y": 5,
      "z": 4,
      "name": "Rock_Volcanic_Brick",
      "rotation": 3
    },
    {
      "x": -17,
      "y": 6,
      "z": 4,
      "name": "Rock_Volcanic_Brick",
      "rotation": 3
    },
    {
      "x": -17,
      "y": 7,
      "z": 4,
      "name": "Rock_Volcanic_Brick",
      "rotation": 3
    },
    {
      "x": -17,
      "y": 8,
      "z": 4,
      "name": "Rock_Volcanic_Brick",
      "rotation": 3
    },
    {
      "x": -17,
      "y": 9,
      "z": 4,
      "name": "Rock_Volcanic_Brick",
      "rotation": 3
    },
    {
      "x": -17,
      "y": 10,
      "z": 4,
      "name": "Rock_Volcanic_Brick",
      "rotation": 3
    },
    {
      "x": -17,
      "y": 11,
      "z": 4,
      "name": "Rock_Volcanic_Brick",
      "rotation": 3
    },
    {
      "x": -17,
      "y": 12,
      "z": 4,
      "name": "Rock_Volcanic_Brick",
      "rotation": 3
    },
    {
      "x": -17,
      "y": 13,
      "z": 4,
      "name": "Rock_Volcanic_Brick",
      "rotation": 3
    },
    {
      "x": -17,
      "y": 14,
      "z": 4,
      "name": "Rock_Volcanic_Brick",
      "rotation": 3
    },
    {
      "x": -17,
      "y": 15,
      "z": 4,
      "name": "Rock_Volcanic_Brick",
      "rotation": 3
    },
    {
      "x": -17,
      "y": 16,
      "z": 4,
      "name": "Rock_Volcanic_Brick",
      "rotation": 3
    },
    {
      "x": -17,
      "y": 17,
      "z": 4,
      "name": "Rock_Volcanic_Brick_Stairs",
      "rotation": 10
    },
    {
      "x": -17,
      "y": 18,
      "z": 4,
      "name": "Rock_Volcanic_Brick",
      "rotation": 1
    },
    {
      "x": -17,
      "y": 19,
      "z": 4,
      "name": "Rock_Volcanic_Brick_Stairs"
    },
    {
      "x": -17,
      "y": 0,
      "z": 5,
      "name": "Empty"
    },
    {
      "x": -17,
      "y": 1,
      "z": 5,
      "name": "Rock_Volcanic_Brick",
      "rotation": 3
    },
    {
      "x": -17,
      "y": 2,
      "z": 5,
      "name": "Rock_Volcanic_Brick",
      "rotation": 3
    },
    {
      "x": -17,
      "y": 3,
      "z": 5,
      "name": "Rock_Volcanic_Brick",
      "rotation": 3
    },
    {
      "x": -17,
      "y": 4,
      "z": 5,
      "name": "Rock_Volcanic_Brick_Stairs"
    },
    {
      "x": -17,
      "y": 0,
      "z": 6,
      "name": "Rock_Basalt_Brick_Stairs",
      "rotation": 3
    },
    {
      "x": -17,
      "y": 1,
      "z": 6,
      "name": "Rock_Volcanic_Brick",
      "rotation": 1
    },
    {
      "x": -17,
      "y": 2,
      "z": 6,
      "name": "Rock_Volcanic_Brick",
      "rotation": 1
    },
    {
      "x": -17,
      "y": 3,
      "z": 6,
      "name": "Rock_Volcanic_Brick",
      "rotation": 1
    },
    {
      "x": -17,
      "y": 4,
      "z": 6,
      "name": "Rock_Volcanic_Brick_Stairs",
      "rotation": 2
    },
    {
      "x": -17,
      "y": 0,
      "z": 7,
      "name": "Empty"
    },
    {
      "x": -17,
      "y": 1,
      "z": 7,
      "name": "Rock_Volcanic_Brick",
      "rotation": 3
    },
    {
      "x": -17,
      "y": 2,
      "z": 7,
      "name": "Rock_Volcanic_Brick",
      "rotation": 3
    },
    {
      "x": -17,
      "y": 3,
      "z": 7,
      "name": "Rock_Volcanic_Brick",
      "rotation": 3
    },
    {
      "x": -17,
      "y": 4,
      "z": 7,
      "name": "Rock_Volcanic_Brick",
      "rotation": 3
    },
    {
      "x": -17,
      "y": 5,
      "z": 7,
      "name": "Rock_Volcanic_Brick",
      "rotation": 3
    },
    {
      "x": -17,
      "y": 6,
      "z": 7,
      "name": "Rock_Volcanic_Brick",
      "rotation": 3
    },
    {
      "x": -17,
      "y": 7,
      "z": 7,
      "name": "Rock_Volcanic_Brick",
      "rotation": 3
    },
    {
      "x": -17,
      "y": 8,
      "z": 7,
      "name": "Rock_Volcanic_Brick",
      "rotation": 3
    },
    {
      "x": -17,
      "y": 9,
      "z": 7,
      "name": "Rock_Volcanic_Brick",
      "rotation": 3
    },
    {
      "x": -17,
      "y": 10,
      "z": 7,
      "name": "Rock_Volcanic_Brick",
      "rotation": 3
    },
    {
      "x": -17,
      "y": 11,
      "z": 7,
      "name": "Rock_Volcanic_Brick",
      "rotation": 3
    },
    {
      "x": -17,
      "y": 12,
      "z": 7,
      "name": "Rock_Volcanic_Brick",
      "rotation": 3
    },
    {
      "x": -17,
      "y": 13,
      "z": 7,
      "name": "Rock_Volcanic_Brick",
      "rotation": 3
    },
    {
      "x": -17,
      "y": 14,
      "z": 7,
      "name": "Rock_Volcanic_Brick",
      "rotation": 3
    },
    {
      "x": -17,
      "y": 15,
      "z": 7,
      "name": "Rock_Volcanic_Brick",
      "rotation": 3
    },
    {
      "x": -17,
      "y": 16,
      "z": 7,
      "name": "Rock_Volcanic_Brick",
      "rotation": 3
    },
    {
      "x": -17,
      "y": 0,
      "z": 8,
      "name": "Empty"
    },
    {
      "x": -17,
      "y": 1,
      "z": 8,
      "name": "Rock_Volcanic_Brick",
      "rotation": 3
    },
    {
      "x": -17,
      "y": 2,
      "z": 8,
      "name": "Rock_Volcanic_Brick",
      "rotation": 3
    },
    {
      "x": -17,
      "y": 3,
      "z": 8,
      "name": "Rock_Volcanic_Brick",
      "rotation": 3
    },
    {
      "x": -17,
      "y": 4,
      "z": 8,
      "name": "Rock_Volcanic_Brick",
      "rotation": 3
    },
    {
      "x": -17,
      "y": 13,
      "z": 8,
      "name": "Rock_Volcanic_Brick_Stairs",
      "rotation": 9
    },
    {
      "x": -17,
      "y": 14,
      "z": 8,
      "name": "Rock_Volcanic_Brick_Ornate",
      "rotation": 3
    },
    {
      "x": -17,
      "y": 15,
      "z": 8,
      "name": "Rock_Volcanic_Brick_Stairs",
      "rotation": 3
    },
    {
      "x": -17,
      "y": 16,
      "z": 8,
      "name": "Rock_Volcanic_Brick_Stairs",
      "rotation": 9
    },
    {
      "x": -17,
      "y": 0,
      "z": 9,
      "name": "Empty"
    },
    {
      "x": -17,
      "y": 1,
      "z": 9,
      "name": "Rock_Volcanic_Brick",
      "rotation": 3
    },
    {
      "x": -17,
      "y": 2,
      "z": 9,
      "name": "Rock_Volcanic_Brick",
      "rotation": 3
    },
    {
      "x": -17,
      "y": 3,
      "z": 9,
      "name": "Rock_Volcanic_Brick",
      "rotation": 3
    },
    {
      "x": -17,
      "y": 4,
      "z": 9,
      "name": "Rock_Volcanic_Brick",
      "rotation": 3
    },
    {
      "x": -17,
      "y": 5,
      "z": 9,
      "name": "Rock_Volcanic_Brick",
      "rotation": 3
    },
    {
      "x": -17,
      "y": 6,
      "z": 9,
      "name": "Rock_Volcanic_Brick",
      "rotation": 3
    },
    {
      "x": -17,
      "y": 7,
      "z": 9,
      "name": "Rock_Volcanic_Brick",
      "rotation": 3
    },
    {
      "x": -17,
      "y": 8,
      "z": 9,
      "name": "Rock_Volcanic_Brick",
      "rotation": 3
    },
    {
      "x": -17,
      "y": 9,
      "z": 9,
      "name": "Rock_Volcanic_Brick",
      "rotation": 3
    },
    {
      "x": -17,
      "y": 10,
      "z": 9,
      "name": "Rock_Volcanic_Brick",
      "rotation": 3
    },
    {
      "x": -17,
      "y": 11,
      "z": 9,
      "name": "Rock_Volcanic_Brick",
      "rotation": 3
    },
    {
      "x": -17,
      "y": 12,
      "z": 9,
      "name": "Rock_Volcanic_Brick",
      "rotation": 3
    },
    {
      "x": -17,
      "y": 13,
      "z": 9,
      "name": "Rock_Volcanic_Brick",
      "rotation": 3
    },
    {
      "x": -17,
      "y": 14,
      "z": 9,
      "name": "Rock_Volcanic_Brick",
      "rotation": 3
    },
    {
      "x": -17,
      "y": 15,
      "z": 9,
      "name": "Rock_Volcanic_Brick",
      "rotation": 3
    },
    {
      "x": -17,
      "y": 16,
      "z": 9,
      "name": "Rock_Volcanic_Brick",
      "rotation": 3
    },
    {
      "x": -17,
      "y": 0,
      "z": 10,
      "name": "Empty"
    },
    {
      "x": -17,
      "y": 1,
      "z": 10,
      "name": "Rock_Volcanic_Brick",
      "rotation": 3
    },
    {
      "x": -17,
      "y": 2,
      "z": 10,
      "name": "Rock_Volcanic_Brick",
      "rotation": 3
    },
    {
      "x": -17,
      "y": 3,
      "z": 10,
      "name": "Rock_Volcanic_Brick",
      "rotation": 3
    },
    {
      "x": -17,
      "y": 4,
      "z": 10,
      "name": "Rock_Volcanic_Brick"
    },
    {
      "x": -17,
      "y": 5,
      "z": 10,
      "name": "Rock_Volcanic_Brick"
    },
    {
      "x": -17,
      "y": 0,
      "z": 11,
      "name": "Rock_Basalt_Brick_Stairs",
      "rotation": 3
    },
    {
      "x": -17,
      "y": 0,
      "z": 12,
      "name": "Rock_Basalt_Brick_Stairs",
      "rotation": 3
    },
    {
      "x": -17,
      "y": 0,
      "z": 13,
      "name": "Empty"
    },
    {
      "x": -17,
      "y": 1,
      "z": 13,
      "name": "Rock_Volcanic_Brick",
      "rotation": 3
    },
    {
      "x": -17,
      "y": 2,
      "z": 13,
      "name": "Rock_Volcanic_Brick",
      "rotation": 3
    },
    {
      "x": -17,
      "y": 3,
      "z": 13,
      "name": "Rock_Volcanic_Brick",
      "rotation": 3
    },
    {
      "x": -17,
      "y": 4,
      "z": 13,
      "name": "Rock_Volcanic_Brick"
    },
    {
      "x": -17,
      "y": 5,
      "z": 13,
      "name": "Rock_Volcanic_Brick"
    },
    {
      "x": -17,
      "y": 0,
      "z": 14,
      "name": "Empty"
    },
    {
      "x": -17,
      "y": 1,
      "z": 14,
      "name": "Rock_Volcanic_Brick",
      "rotation": 3
    },
    {
      "x": -17,
      "y": 2,
      "z": 14,
      "name": "Rock_Volcanic_Brick",
      "rotation": 3
    },
    {
      "x": -17,
      "y": 3,
      "z": 14,
      "name": "Rock_Volcanic_Brick",
      "rotation": 3
    },
    {
      "x": -17,
      "y": 4,
      "z": 14,
      "name": "Rock_Volcanic_Brick",
      "rotation": 3
    },
    {
      "x": -17,
      "y": 5,
      "z": 14,
      "name": "Rock_Volcanic_Brick",
      "rotation": 3
    },
    {
      "x": -17,
      "y": 6,
      "z": 14,
      "name": "Rock_Volcanic_Brick",
      "rotation": 3
    },
    {
      "x": -17,
      "y": 7,
      "z": 14,
      "name": "Rock_Volcanic_Brick",
      "rotation": 3
    },
    {
      "x": -17,
      "y": 8,
      "z": 14,
      "name": "Rock_Volcanic_Brick",
      "rotation": 3
    },
    {
      "x": -17,
      "y": 9,
      "z": 14,
      "name": "Rock_Volcanic_Brick",
      "rotation": 3
    },
    {
      "x": -17,
      "y": 10,
      "z": 14,
      "name": "Rock_Volcanic_Brick",
      "rotation": 3
    },
    {
      "x": -17,
      "y": 11,
      "z": 14,
      "name": "Rock_Volcanic_Brick",
      "rotation": 3
    },
    {
      "x": -17,
      "y": 12,
      "z": 14,
      "name": "Rock_Volcanic_Brick",
      "rotation": 3
    },
    {
      "x": -17,
      "y": 13,
      "z": 14,
      "name": "Rock_Volcanic_Brick",
      "rotation": 3
    },
    {
      "x": -17,
      "y": 14,
      "z": 14,
      "name": "Rock_Volcanic_Brick",
      "rotation": 3
    },
    {
      "x": -17,
      "y": 15,
      "z": 14,
      "name": "Rock_Volcanic_Brick",
      "rotation": 3
    },
    {
      "x": -17,
      "y": 16,
      "z": 14,
      "name": "Rock_Volcanic_Brick",
      "rotation": 3
    },
    {
      "x": -17,
      "y": 17,
      "z": 14,
      "name": "Rock_Volcanic_Brick",
      "rotation": 3
    },
    {
      "x": -17,
      "y": 18,
      "z": 14,
      "name": "Rock_Volcanic_Brick",
      "rotation": 3
    },
    {
      "x": -17,
      "y": 19,
      "z": 14,
      "name": "Rock_Volcanic_Brick",
      "rotation": 3
    },
    {
      "x": -17,
      "y": 0,
      "z": 15,
      "name": "Empty"
    },
    {
      "x": -17,
      "y": 1,
      "z": 15,
      "name": "Rock_Volcanic_Brick",
      "rotation": 3
    },
    {
      "x": -17,
      "y": 2,
      "z": 15,
      "name": "Rock_Volcanic_Brick",
      "rotation": 3
    },
    {
      "x": -17,
      "y": 3,
      "z": 15,
      "name": "Rock_Volcanic_Brick",
      "rotation": 3
    },
    {
      "x": -17,
      "y": 4,
      "z": 15,
      "name": "Rock_Volcanic_Brick",
      "rotation": 3
    },
    {
      "x": -17,
      "y": 13,
      "z": 15,
      "name": "Rock_Volcanic_Brick_Stairs",
      "rotation": 9
    },
    {
      "x": -17,
      "y": 14,
      "z": 15,
      "name": "Rock_Volcanic_Brick_Ornate",
      "rotation": 3
    },
    {
      "x": -17,
      "y": 15,
      "z": 15,
      "name": "Rock_Volcanic_Brick_Stairs",
      "rotation": 3
    },
    {
      "x": -17,
      "y": 16,
      "z": 15,
      "name": "Rock_Volcanic_Brick_Stairs",
      "rotation": 9
    },
    {
      "x": -17,
      "y": 17,
      "z": 15,
      "name": "Rock_Volcanic_Brick_Ornate",
      "rotation": 3
    },
    {
      "x": -17,
      "y": 0,
      "z": 16,
      "name": "Empty"
    },
    {
      "x": -17,
      "y": 1,
      "z": 16,
      "name": "Rock_Volcanic_Brick",
      "rotation": 3
    },
    {
      "x": -17,
      "y": 2,
      "z": 16,
      "name": "Rock_Volcanic_Brick",
      "rotation": 3
    },
    {
      "x": -17,
      "y": 3,
      "z": 16,
      "name": "Rock_Volcanic_Brick",
      "rotation": 3
    },
    {
      "x": -17,
      "y": 4,
      "z": 16,
      "name": "Rock_Volcanic_Brick",
      "rotation": 3
    },
    {
      "x": -17,
      "y": 5,
      "z": 16,
      "name": "Rock_Volcanic_Brick",
      "rotation": 3
    },
    {
      "x": -17,
      "y": 6,
      "z": 16,
      "name": "Rock_Volcanic_Brick",
      "rotation": 3
    },
    {
      "x": -17,
      "y": 7,
      "z": 16,
      "name": "Rock_Volcanic_Brick",
      "rotation": 3
    },
    {
      "x": -17,
      "y": 8,
      "z": 16,
      "name": "Rock_Volcanic_Brick",
      "rotation": 3
    },
    {
      "x": -17,
      "y": 9,
      "z": 16,
      "name": "Rock_Volcanic_Brick",
      "rotation": 3
    },
    {
      "x": -17,
      "y": 10,
      "z": 16,
      "name": "Rock_Volcanic_Brick",
      "rotation": 3
    },
    {
      "x": -17,
      "y": 11,
      "z": 16,
      "name": "Rock_Volcanic_Brick",
      "rotation": 3
    },
    {
      "x": -17,
      "y": 12,
      "z": 16,
      "name": "Rock_Volcanic_Brick",
      "rotation": 3
    },
    {
      "x": -17,
      "y": 13,
      "z": 16,
      "name": "Rock_Volcanic_Brick",
      "rotation": 3
    },
    {
      "x": -17,
      "y": 14,
      "z": 16,
      "name": "Rock_Volcanic_Brick",
      "rotation": 3
    },
    {
      "x": -17,
      "y": 15,
      "z": 16,
      "name": "Rock_Volcanic_Brick",
      "rotation": 3
    },
    {
      "x": -17,
      "y": 16,
      "z": 16,
      "name": "Rock_Volcanic_Brick",
      "rotation": 3
    },
    {
      "x": -17,
      "y": 17,
      "z": 16,
      "name": "Rock_Volcanic_Brick_Stairs",
      "rotation": 8
    },
    {
      "x": -17,
      "y": 0,
      "z": 17,
      "name": "Empty"
    },
    {
      "x": -17,
      "y": 1,
      "z": 17,
      "name": "Rock_Volcanic_Brick",
      "rotation": 3
    },
    {
      "x": -17,
      "y": 2,
      "z": 17,
      "name": "Rock_Volcanic_Brick",
      "rotation": 3
    },
    {
      "x": -17,
      "y": 3,
      "z": 17,
      "name": "Rock_Volcanic_Brick",
      "rotation": 3
    },
    {
      "x": -17,
      "y": 4,
      "z": 17,
      "name": "Rock_Volcanic_Brick",
      "rotation": 3
    },
    {
      "x": -17,
      "y": 13,
      "z": 17,
      "name": "Rock_Volcanic_Brick_Stairs",
      "rotation": 9
    },
    {
      "x": -17,
      "y": 14,
      "z": 17,
      "name": "Rock_Volcanic_Brick_Stairs",
      "rotation": 3
    },
    {
      "x": -17,
      "y": 15,
      "z": 17,
      "name": "Rock_Volcanic_Brick_Ornate",
      "rotation": 3
    },
    {
      "x": -17,
      "y": 16,
      "z": 17,
      "name": "Rock_Volcanic_Brick_Stairs",
      "rotation": 8
    },
    {
      "x": -17,
      "y": 17,
      "z": 17,
      "name": "Rock_Crystal_Purple_Small",
      "rotation": 7
    },
    {
      "x": -17,
      "y": 0,
      "z": 18,
      "name": "Empty"
    },
    {
      "x": -17,
      "y": 1,
      "z": 18,
      "name": "Rock_Volcanic_Brick",
      "rotation": 3
    },
    {
      "x": -17,
      "y": 2,
      "z": 18,
      "name": "Rock_Volcanic_Brick",
      "rotation": 3
    },
    {
      "x": -17,
      "y": 3,
      "z": 18,
      "name": "Rock_Volcanic_Brick",
      "rotation": 3
    },
    {
      "x": -17,
      "y": 4,
      "z": 18,
      "name": "Rock_Volcanic_Brick",
      "rotation": 3
    },
    {
      "x": -17,
      "y": 5,
      "z": 18,
      "name": "Rock_Volcanic_Brick",
      "rotation": 3
    },
    {
      "x": -17,
      "y": 6,
      "z": 18,
      "name": "Rock_Volcanic_Brick",
      "rotation": 3
    },
    {
      "x": -17,
      "y": 7,
      "z": 18,
      "name": "Rock_Volcanic_Brick",
      "rotation": 3
    },
    {
      "x": -17,
      "y": 8,
      "z": 18,
      "name": "Rock_Volcanic_Brick",
      "rotation": 3
    },
    {
      "x": -17,
      "y": 9,
      "z": 18,
      "name": "Rock_Volcanic_Brick",
      "rotation": 3
    },
    {
      "x": -17,
      "y": 10,
      "z": 18,
      "name": "Rock_Volcanic_Brick",
      "rotation": 3
    },
    {
      "x": -17,
      "y": 11,
      "z": 18,
      "name": "Rock_Volcanic_Brick",
      "rotation": 3
    },
    {
      "x": -17,
      "y": 12,
      "z": 18,
      "name": "Rock_Volcanic_Brick",
      "rotation": 3
    },
    {
      "x": -17,
      "y": 13,
      "z": 18,
      "name": "Rock_Volcanic_Brick",
      "rotation": 3
    },
    {
      "x": -17,
      "y": 14,
      "z": 18,
      "name": "Rock_Volcanic_Brick",
      "rotation": 3
    },
    {
      "x": -17,
      "y": 15,
      "z": 18,
      "name": "Rock_Volcanic_Brick_Stairs",
      "rotation": 8
    },
    {
      "x": -17,
      "y": 0,
      "z": 19,
      "name": "Empty"
    },
    {
      "x": -17,
      "y": 1,
      "z": 19,
      "name": "Rock_Volcanic_Brick",
      "rotation": 3
    },
    {
      "x": -17,
      "y": 2,
      "z": 19,
      "name": "Rock_Volcanic_Brick",
      "rotation": 3
    },
    {
      "x": -17,
      "y": 3,
      "z": 19,
      "name": "Rock_Volcanic_Brick",
      "rotation": 3
    },
    {
      "x": -17,
      "y": 4,
      "z": 19,
      "name": "Rock_Volcanic_Brick",
      "rotation": 3
    },
    {
      "x": -17,
      "y": 12,
      "z": 19,
      "name": "Rock_Volcanic_Brick_Stairs",
      "rotation": 9
    },
    {
      "x": -17,
      "y": 13,
      "z": 19,
      "name": "Rock_Volcanic_Brick_Stairs",
      "rotation": 3
    },
    {
      "x": -17,
      "y": 14,
      "z": 19,
      "name": "Rock_Volcanic_Brick_Ornate",
      "rotation": 3
    },
    {
      "x": -17,
      "y": 0,
      "z": 20,
      "name": "Empty"
    },
    {
      "x": -17,
      "y": 1,
      "z": 20,
      "name": "Rock_Volcanic_Brick",
      "rotation": 3
    },
    {
      "x": -17,
      "y": 2,
      "z": 20,
      "name": "Rock_Volcanic_Brick",
      "rotation": 3
    },
    {
      "x": -17,
      "y": 3,
      "z": 20,
      "name": "Rock_Volcanic_Brick",
      "rotation": 3
    },
    {
      "x": -17,
      "y": 4,
      "z": 20,
      "name": "Rock_Volcanic_Brick",
      "rotation": 3
    },
    {
      "x": -17,
      "y": 5,
      "z": 20,
      "name": "Rock_Volcanic_Brick",
      "rotation": 3
    },
    {
      "x": -17,
      "y": 6,
      "z": 20,
      "name": "Rock_Volcanic_Brick",
      "rotation": 3
    },
    {
      "x": -17,
      "y": 7,
      "z": 20,
      "name": "Rock_Volcanic_Brick",
      "rotation": 3
    },
    {
      "x": -17,
      "y": 8,
      "z": 20,
      "name": "Rock_Volcanic_Brick",
      "rotation": 3
    },
    {
      "x": -17,
      "y": 9,
      "z": 20,
      "name": "Rock_Volcanic_Brick",
      "rotation": 3
    },
    {
      "x": -17,
      "y": 10,
      "z": 20,
      "name": "Rock_Volcanic_Brick",
      "rotation": 3
    },
    {
      "x": -17,
      "y": 11,
      "z": 20,
      "name": "Rock_Volcanic_Brick",
      "rotation": 3
    },
    {
      "x": -17,
      "y": 12,
      "z": 20,
      "name": "Rock_Volcanic_Brick",
      "rotation": 3
    },
    {
      "x": -17,
      "y": 13,
      "z": 20,
      "name": "Rock_Volcanic_Brick",
      "rotation": 3
    },
    {
      "x": -17,
      "y": 14,
      "z": 20,
      "name": "Rock_Volcanic_Brick_Stairs",
      "rotation": 8
    },
    {
      "x": -17,
      "y": 0,
      "z": 21,
      "name": "Empty"
    },
    {
      "x": -17,
      "y": 1,
      "z": 21,
      "name": "Rock_Volcanic_Brick",
      "rotation": 3
    },
    {
      "x": -17,
      "y": 2,
      "z": 21,
      "name": "Rock_Volcanic_Brick",
      "rotation": 3
    },
    {
      "x": -17,
      "y": 3,
      "z": 21,
      "name": "Rock_Volcanic_Brick",
      "rotation": 3
    },
    {
      "x": -17,
      "y": 4,
      "z": 21,
      "name": "Rock_Volcanic_Brick_Stairs"
    },
    {
      "x": -17,
      "y": 0,
      "z": 22,
      "name": "Empty"
    },
    {
      "x": -17,
      "y": 0,
      "z": 23,
      "name": "Empty"
    },
    {
      "x": -16,
      "y": 0,
      "z": -22,
      "name": "Empty"
    },
    {
      "x": -16,
      "y": 0,
      "z": -21,
      "name": "Empty"
    },
    {
      "x": -16,
      "y": 0,
      "z": -20,
      "name": "Empty"
    },
    {
      "x": -16,
      "y": 0,
      "z": -19,
      "name": "Empty"
    },
    {
      "x": -16,
      "y": 0,
      "z": -18,
      "name": "Empty"
    },
    {
      "x": -16,
      "y": 0,
      "z": -17,
      "name": "Empty"
    },
    {
      "x": -16,
      "y": 0,
      "z": -16,
      "name": "Empty"
    },
    {
      "x": -16,
      "y": 0,
      "z": -15,
      "name": "Empty"
    },
    {
      "x": -16,
      "y": 0,
      "z": -14,
      "name": "Empty"
    },
    {
      "x": -16,
      "y": 0,
      "z": -13,
      "name": "Empty"
    },
    {
      "x": -16,
      "y": 1,
      "z": -13,
      "name": "Rock_Volcanic_Brick_Wall",
      "rotation": 2
    },
    {
      "x": -16,
      "y": 2,
      "z": -13,
      "name": "Rock_Volcanic_Cobble_Beam",
      "rotation": 2
    },
    {
      "x": -16,
      "y": 3,
      "z": -13,
      "name": "Rock_Volcanic_Brick_Beam",
      "rotation": 2
    },
    {
      "x": -16,
      "y": 4,
      "z": -13,
      "name": "Wood_Deadwood_Beam",
      "rotation": 2
    },
    {
      "x": -16,
      "y": 5,
      "z": -13,
      "name": "Wood_Deadwood_Beam",
      "rotation": 2
    },
    {
      "x": -16,
      "y": 0,
      "z": -12,
      "name": "Empty"
    },
    {
      "x": -16,
      "y": 1,
      "z": -12,
      "name": "Rock_Volcanic_Brick",
      "rotation": 2
    },
    {
      "x": -16,
      "y": 2,
      "z": -12,
      "name": "Rock_Volcanic_Brick",
      "rotation": 2
    },
    {
      "x": -16,
      "y": 3,
      "z": -12,
      "name": "Rock_Volcanic_Brick",
      "rotation": 2
    },
    {
      "x": -16,
      "y": 4,
      "z": -12,
      "name": "Rock_Volcanic_Brick",
      "rotation": 2
    },
    {
      "x": -16,
      "y": 12,
      "z": -12,
      "name": "Rock_Volcanic_Brick_Stairs",
      "rotation": 8
    },
    {
      "x": -16,
      "y": 13,
      "z": -12,
      "name": "Rock_Volcanic_Brick_Stairs",
      "rotation": 2
    },
    {
      "x": -16,
      "y": 14,
      "z": -12,
      "name": "Rock_Volcanic_Brick_Ornate",
      "rotation": 2
    },
    {
      "x": -16,
      "y": 0,
      "z": -11,
      "name": "Empty"
    },
    {
      "x": -16,
      "y": 1,
      "z": -11,
      "name": "Rock_Volcanic_Brick",
      "rotation": 3
    },
    {
      "x": -16,
      "y": 2,
      "z": -11,
      "name": "Rock_Volcanic_Brick",
      "rotation": 3
    },
    {
      "x": -16,
      "y": 3,
      "z": -11,
      "name": "Rock_Volcanic_Brick",
      "rotation": 3
    },
    {
      "x": -16,
      "y": 4,
      "z": -11,
      "name": "Rock_Slate",
      "rotation": 3
    },
    {
      "x": -16,
      "y": 5,
      "z": -11,
      "name": "Rock_Slate",
      "rotation": 3
    },
    {
      "x": -16,
      "y": 6,
      "z": -11,
      "name": "Rock_Slate",
      "rotation": 3
    },
    {
      "x": -16,
      "y": 7,
      "z": -11,
      "name": "Rock_Slate",
      "rotation": 3
    },
    {
      "x": -16,
      "y": 8,
      "z": -11,
      "name": "Rock_Slate",
      "rotation": 3
    },
    {
      "x": -16,
      "y": 9,
      "z": -11,
      "name": "Rock_Slate",
      "rotation": 3
    },
    {
      "x": -16,
      "y": 10,
      "z": -11,
      "name": "Rock_Slate",
      "rotation": 3
    },
    {
      "x": -16,
      "y": 11,
      "z": -11,
      "name": "Rock_Slate",
      "rotation": 3
    },
    {
      "x": -16,
      "y": 12,
      "z": -11,
      "name": "Rock_Slate",
      "rotation": 3
    },
    {
      "x": -16,
      "y": 13,
      "z": -11,
      "name": "Rock_Slate",
      "rotation": 3
    },
    {
      "x": -16,
      "y": 14,
      "z": -11,
      "name": "Rock_Crystal_Purple_Block",
      "rotation": 3
    },
    {
      "x": -16,
      "y": 15,
      "z": -11,
      "name": "Rock_Crystal_Purple_Block",
      "rotation": 3
    },
    {
      "x": -16,
      "y": 16,
      "z": -11,
      "name": "Rock_Crystal_Purple_Large",
      "rotation": 3
    },
    {
      "x": -16,
      "y": 0,
      "z": -10,
      "name": "Empty"
    },
    {
      "x": -16,
      "y": 1,
      "z": -10,
      "name": "Rock_Volcanic_Brick",
      "rotation": 3
    },
    {
      "x": -16,
      "y": 2,
      "z": -10,
      "name": "Rock_Volcanic_Brick",
      "rotation": 3
    },
    {
      "x": -16,
      "y": 3,
      "z": -10,
      "name": "Rock_Volcanic_Brick",
      "rotation": 3
    },
    {
      "x": -16,
      "y": 4,
      "z": -10,
      "name": "Rock_Slate",
      "rotation": 3
    },
    {
      "x": -16,
      "y": 5,
      "z": -10,
      "name": "Rock_Slate",
      "rotation": 3
    },
    {
      "x": -16,
      "y": 6,
      "z": -10,
      "name": "Rock_Slate",
      "rotation": 3
    },
    {
      "x": -16,
      "y": 7,
      "z": -10,
      "name": "Rock_Slate",
      "rotation": 3
    },
    {
      "x": -16,
      "y": 8,
      "z": -10,
      "name": "Rock_Slate",
      "rotation": 3
    },
    {
      "x": -16,
      "y": 9,
      "z": -10,
      "name": "Rock_Slate",
      "rotation": 3
    },
    {
      "x": -16,
      "y": 10,
      "z": -10,
      "name": "Rock_Slate",
      "rotation": 3
    },
    {
      "x": -16,
      "y": 11,
      "z": -10,
      "name": "Rock_Slate",
      "rotation": 3
    },
    {
      "x": -16,
      "y": 12,
      "z": -10,
      "name": "Rock_Slate",
      "rotation": 3
    },
    {
      "x": -16,
      "y": 13,
      "z": -10,
      "name": "Rock_Slate",
      "rotation": 3
    },
    {
      "x": -16,
      "y": 14,
      "z": -10,
      "name": "Rock_Crystal_Purple_Block",
      "rotation": 3
    },
    {
      "x": -16,
      "y": 15,
      "z": -10,
      "name": "Rock_Crystal_Purple_Block",
      "rotation": 3
    },
    {
      "x": -16,
      "y": 16,
      "z": -10,
      "name": "Rock_Crystal_Purple_Block",
      "rotation": 3
    },
    {
      "x": -16,
      "y": 17,
      "z": -10,
      "name": "Rock_Crystal_Purple_Block",
      "rotation": 3
    },
    {
      "x": -16,
      "y": 18,
      "z": -10,
      "name": "Rock_Crystal_Purple_Large",
      "rotation": 6
    },
    {
      "x": -16,
      "y": 19,
      "z": -10,
      "name": "Rock_Crystal_Purple_Block",
      "rotation": 3
    },
    {
      "x": -16,
      "y": 21,
      "z": -10,
      "name": "Rock_Volcanic",
      "rotation": 3
    },
    {
      "x": -16,
      "y": 22,
      "z": -10,
      "name": "Rock_Volcanic",
      "rotation": 3
    },
    {
      "x": -16,
      "y": 0,
      "z": -9,
      "name": "Empty"
    },
    {
      "x": -16,
      "y": 1,
      "z": -9,
      "name": "Rock_Volcanic_Brick",
      "rotation": 3
    },
    {
      "x": -16,
      "y": 2,
      "z": -9,
      "name": "Rock_Volcanic_Brick",
      "rotation": 3
    },
    {
      "x": -16,
      "y": 3,
      "z": -9,
      "name": "Rock_Volcanic_Brick",
      "rotation": 3
    },
    {
      "x": -16,
      "y": 4,
      "z": -9,
      "name": "Rock_Slate",
      "rotation": 3
    },
    {
      "x": -16,
      "y": 5,
      "z": -9,
      "name": "Rock_Slate",
      "rotation": 3
    },
    {
      "x": -16,
      "y": 6,
      "z": -9,
      "name": "Rock_Slate",
      "rotation": 3
    },
    {
      "x": -16,
      "y": 7,
      "z": -9,
      "name": "Rock_Slate",
      "rotation": 3
    },
    {
      "x": -16,
      "y": 8,
      "z": -9,
      "name": "Rock_Slate",
      "rotation": 3
    },
    {
      "x": -16,
      "y": 9,
      "z": -9,
      "name": "Rock_Slate",
      "rotation": 3
    },
    {
      "x": -16,
      "y": 10,
      "z": -9,
      "name": "Rock_Slate",
      "rotation": 3
    },
    {
      "x": -16,
      "y": 11,
      "z": -9,
      "name": "Rock_Slate",
      "rotation": 3
    },
    {
      "x": -16,
      "y": 12,
      "z": -9,
      "name": "Rock_Slate",
      "rotation": 3
    },
    {
      "x": -16,
      "y": 13,
      "z": -9,
      "name": "Rock_Slate",
      "rotation": 3
    },
    {
      "x": -16,
      "y": 14,
      "z": -9,
      "name": "Rock_Crystal_Purple_Block",
      "rotation": 3
    },
    {
      "x": -16,
      "y": 15,
      "z": -9,
      "name": "Rock_Crystal_Purple_Block",
      "rotation": 3
    },
    {
      "x": -16,
      "y": 16,
      "z": -9,
      "name": "Rock_Crystal_Purple_Block",
      "rotation": 3
    },
    {
      "x": -16,
      "y": 17,
      "z": -9,
      "name": "Rock_Crystal_Purple_Block",
      "rotation": 3
    },
    {
      "x": -16,
      "y": 18,
      "z": -9,
      "name": "Rock_Crystal_Purple_Block",
      "rotation": 3
    },
    {
      "x": -16,
      "y": 19,
      "z": -9,
      "name": "Rock_Crystal_Purple_Block",
      "rotation": 3
    },
    {
      "x": -16,
      "y": 20,
      "z": -9,
      "name": "Rock_Volcanic",
      "rotation": 3
    },
    {
      "x": -16,
      "y": 21,
      "z": -9,
      "name": "Rock_Volcanic",
      "rotation": 3
    },
    {
      "x": -16,
      "y": 22,
      "z": -9,
      "name": "Rock_Volcanic",
      "rotation": 3
    },
    {
      "x": -16,
      "y": 0,
      "z": -8,
      "name": "Empty"
    },
    {
      "x": -16,
      "y": 1,
      "z": -8,
      "name": "Rock_Volcanic_Brick",
      "rotation": 3
    },
    {
      "x": -16,
      "y": 2,
      "z": -8,
      "name": "Rock_Volcanic_Brick",
      "rotation": 3
    },
    {
      "x": -16,
      "y": 3,
      "z": -8,
      "name": "Rock_Volcanic_Brick",
      "rotation": 3
    },
    {
      "x": -16,
      "y": 4,
      "z": -8,
      "name": "Rock_Slate",
      "rotation": 3
    },
    {
      "x": -16,
      "y": 5,
      "z": -8,
      "name": "Rock_Slate",
      "rotation": 3
    },
    {
      "x": -16,
      "y": 6,
      "z": -8,
      "name": "Rock_Slate",
      "rotation": 3
    },
    {
      "x": -16,
      "y": 7,
      "z": -8,
      "name": "Rock_Slate",
      "rotation": 3
    },
    {
      "x": -16,
      "y": 8,
      "z": -8,
      "name": "Rock_Slate",
      "rotation": 3
    },
    {
      "x": -16,
      "y": 9,
      "z": -8,
      "name": "Rock_Slate",
      "rotation": 3
    },
    {
      "x": -16,
      "y": 10,
      "z": -8,
      "name": "Rock_Slate",
      "rotation": 3
    },
    {
      "x": -16,
      "y": 11,
      "z": -8,
      "name": "Rock_Slate",
      "rotation": 3
    },
    {
      "x": -16,
      "y": 12,
      "z": -8,
      "name": "Rock_Slate",
      "rotation": 3
    },
    {
      "x": -16,
      "y": 13,
      "z": -8,
      "name": "Rock_Slate",
      "rotation": 3
    },
    {
      "x": -16,
      "y": 14,
      "z": -8,
      "name": "Rock_Crystal_Purple_Block",
      "rotation": 3
    },
    {
      "x": -16,
      "y": 15,
      "z": -8,
      "name": "Rock_Crystal_Purple_Block",
      "rotation": 3
    },
    {
      "x": -16,
      "y": 16,
      "z": -8,
      "name": "Rock_Crystal_Purple_Block",
      "rotation": 3
    },
    {
      "x": -16,
      "y": 17,
      "z": -8,
      "name": "Rock_Crystal_Purple_Block",
      "rotation": 3
    },
    {
      "x": -16,
      "y": 18,
      "z": -8,
      "name": "Rock_Crystal_Purple_Block",
      "rotation": 3
    },
    {
      "x": -16,
      "y": 19,
      "z": -8,
      "name": "Rock_Volcanic",
      "rotation": 3
    },
    {
      "x": -16,
      "y": 20,
      "z": -8,
      "name": "Rock_Volcanic",
      "rotation": 3
    },
    {
      "x": -16,
      "y": 21,
      "z": -8,
      "name": "Rock_Volcanic",
      "rotation": 3
    },
    {
      "x": -16,
      "y": 0,
      "z": -7,
      "name": "Empty"
    },
    {
      "x": -16,
      "y": 1,
      "z": -7,
      "name": "Rock_Volcanic_Brick",
      "rotation": 3
    },
    {
      "x": -16,
      "y": 2,
      "z": -7,
      "name": "Rock_Volcanic_Brick",
      "rotation": 3
    },
    {
      "x": -16,
      "y": 3,
      "z": -7,
      "name": "Rock_Volcanic_Brick",
      "rotation": 3
    },
    {
      "x": -16,
      "y": 4,
      "z": -7,
      "name": "Rock_Slate",
      "rotation": 3
    },
    {
      "x": -16,
      "y": 5,
      "z": -7,
      "name": "Rock_Slate",
      "rotation": 3
    },
    {
      "x": -16,
      "y": 6,
      "z": -7,
      "name": "Rock_Slate",
      "rotation": 3
    },
    {
      "x": -16,
      "y": 7,
      "z": -7,
      "name": "Rock_Slate",
      "rotation": 3
    },
    {
      "x": -16,
      "y": 8,
      "z": -7,
      "name": "Rock_Slate",
      "rotation": 3
    },
    {
      "x": -16,
      "y": 9,
      "z": -7,
      "name": "Rock_Slate",
      "rotation": 3
    },
    {
      "x": -16,
      "y": 10,
      "z": -7,
      "name": "Rock_Slate",
      "rotation": 3
    },
    {
      "x": -16,
      "y": 11,
      "z": -7,
      "name": "Rock_Slate",
      "rotation": 3
    },
    {
      "x": -16,
      "y": 12,
      "z": -7,
      "name": "Rock_Slate",
      "rotation": 3
    },
    {
      "x": -16,
      "y": 13,
      "z": -7,
      "name": "Rock_Slate",
      "rotation": 3
    },
    {
      "x": -16,
      "y": 14,
      "z": -7,
      "name": "Rock_Volcanic"
    },
    {
      "x": -16,
      "y": 15,
      "z": -7,
      "name": "Rock_Volcanic"
    },
    {
      "x": -16,
      "y": 16,
      "z": -7,
      "name": "Rock_Volcanic"
    },
    {
      "x": -16,
      "y": 17,
      "z": -7,
      "name": "Rock_Volcanic"
    },
    {
      "x": -16,
      "y": 18,
      "z": -7,
      "name": "Rock_Volcanic",
      "rotation": 3
    },
    {
      "x": -16,
      "y": 19,
      "z": -7,
      "name": "Rock_Volcanic",
      "rotation": 3
    },
    {
      "x": -16,
      "y": 20,
      "z": -7,
      "name": "Rock_Volcanic",
      "rotation": 3
    },
    {
      "x": -16,
      "y": 0,
      "z": -6,
      "name": "Empty"
    },
    {
      "x": -16,
      "y": 1,
      "z": -6,
      "name": "Rock_Volcanic_Brick",
      "rotation": 3
    },
    {
      "x": -16,
      "y": 2,
      "z": -6,
      "name": "Rock_Volcanic_Brick",
      "rotation": 3
    },
    {
      "x": -16,
      "y": 3,
      "z": -6,
      "name": "Rock_Volcanic_Brick",
      "rotation": 3
    },
    {
      "x": -16,
      "y": 4,
      "z": -6,
      "name": "Rock_Slate",
      "rotation": 1
    },
    {
      "x": -16,
      "y": 5,
      "z": -6,
      "name": "Rock_Slate",
      "rotation": 1
    },
    {
      "x": -16,
      "y": 6,
      "z": -6,
      "name": "Rock_Slate",
      "rotation": 1
    },
    {
      "x": -16,
      "y": 7,
      "z": -6,
      "name": "Rock_Slate",
      "rotation": 1
    },
    {
      "x": -16,
      "y": 8,
      "z": -6,
      "name": "Rock_Slate",
      "rotation": 1
    },
    {
      "x": -16,
      "y": 9,
      "z": -6,
      "name": "Rock_Slate",
      "rotation": 1
    },
    {
      "x": -16,
      "y": 10,
      "z": -6,
      "name": "Rock_Slate",
      "rotation": 1
    },
    {
      "x": -16,
      "y": 11,
      "z": -6,
      "name": "Rock_Slate",
      "rotation": 1
    },
    {
      "x": -16,
      "y": 12,
      "z": -6,
      "name": "Rock_Slate",
      "rotation": 1
    },
    {
      "x": -16,
      "y": 13,
      "z": -6,
      "name": "Rock_Slate",
      "rotation": 1
    },
    {
      "x": -16,
      "y": 14,
      "z": -6,
      "name": "Rock_Volcanic"
    },
    {
      "x": -16,
      "y": 15,
      "z": -6,
      "name": "Rock_Volcanic"
    },
    {
      "x": -16,
      "y": 16,
      "z": -6,
      "name": "Rock_Volcanic"
    },
    {
      "x": -16,
      "y": 17,
      "z": -6,
      "name": "Rock_Volcanic"
    },
    {
      "x": -16,
      "y": 18,
      "z": -6,
      "name": "Rock_Volcanic",
      "rotation": 3
    },
    {
      "x": -16,
      "y": 19,
      "z": -6,
      "name": "Rock_Volcanic",
      "rotation": 3
    },
    {
      "x": -16,
      "y": 20,
      "z": -6,
      "name": "Rock_Volcanic",
      "rotation": 3
    },
    {
      "x": -16,
      "y": 0,
      "z": -5,
      "name": "Rock_Basalt_Brick_Decorative",
      "rotation": 3
    },
    {
      "x": -16,
      "y": 1,
      "z": -5,
      "name": "Rock_Volcanic_Brick",
      "rotation": 1
    },
    {
      "x": -16,
      "y": 2,
      "z": -5,
      "name": "Rock_Volcanic_Brick",
      "rotation": 1
    },
    {
      "x": -16,
      "y": 3,
      "z": -5,
      "name": "Rock_Volcanic_Brick",
      "rotation": 1
    },
    {
      "x": -16,
      "y": 4,
      "z": -5,
      "name": "Rock_Volcanic",
      "rotation": 1
    },
    {
      "x": -16,
      "y": 5,
      "z": -5,
      "name": "Rock_Volcanic",
      "rotation": 1
    },
    {
      "x": -16,
      "y": 6,
      "z": -5,
      "name": "Rock_Volcanic",
      "rotation": 1
    },
    {
      "x": -16,
      "y": 7,
      "z": -5,
      "name": "Rock_Volcanic",
      "rotation": 1
    },
    {
      "x": -16,
      "y": 8,
      "z": -5,
      "name": "Rock_Volcanic",
      "rotation": 1
    },
    {
      "x": -16,
      "y": 9,
      "z": -5,
      "name": "Rock_Volcanic",
      "rotation": 1
    },
    {
      "x": -16,
      "y": 10,
      "z": -5,
      "name": "Rock_Volcanic",
      "rotation": 1
    },
    {
      "x": -16,
      "y": 11,
      "z": -5,
      "name": "Rock_Volcanic",
      "rotation": 1
    },
    {
      "x": -16,
      "y": 12,
      "z": -5,
      "name": "Rock_Volcanic",
      "rotation": 1
    },
    {
      "x": -16,
      "y": 13,
      "z": -5,
      "name": "Rock_Volcanic",
      "rotation": 1
    },
    {
      "x": -16,
      "y": 14,
      "z": -5,
      "name": "Rock_Volcanic"
    },
    {
      "x": -16,
      "y": 15,
      "z": -5,
      "name": "Rock_Volcanic"
    },
    {
      "x": -16,
      "y": 16,
      "z": -5,
      "name": "Rock_Volcanic"
    },
    {
      "x": -16,
      "y": 17,
      "z": -5,
      "name": "Rock_Volcanic"
    },
    {
      "x": -16,
      "y": 18,
      "z": -5,
      "name": "Rock_Volcanic",
      "rotation": 1
    },
    {
      "x": -16,
      "y": 19,
      "z": -5,
      "name": "Rock_Volcanic",
      "rotation": 1
    },
    {
      "x": -16,
      "y": 20,
      "z": -5,
      "name": "Rock_Volcanic",
      "rotation": 1
    },
    {
      "x": -16,
      "y": 0,
      "z": -4,
      "name": "Rock_Basalt_Brick",
      "rotation": 3
    },
    {
      "x": -16,
      "y": 1,
      "z": -4,
      "name": "Rock_Volcanic_Brick",
      "rotation": 1
    },
    {
      "x": -16,
      "y": 2,
      "z": -4,
      "name": "Rock_Volcanic_Brick",
      "rotation": 1
    },
    {
      "x": -16,
      "y": 3,
      "z": -4,
      "name": "Rock_Volcanic_Brick",
      "rotation": 1
    },
    {
      "x": -16,
      "y": 4,
      "z": -4,
      "name": "Rock_Volcanic",
      "rotation": 1
    },
    {
      "x": -16,
      "y": 5,
      "z": -4,
      "name": "Rock_Volcanic",
      "rotation": 1
    },
    {
      "x": -16,
      "y": 6,
      "z": -4,
      "name": "Rock_Volcanic",
      "rotation": 1
    },
    {
      "x": -16,
      "y": 7,
      "z": -4,
      "name": "Rock_Volcanic",
      "rotation": 1
    },
    {
      "x": -16,
      "y": 8,
      "z": -4,
      "name": "Rock_Volcanic",
      "rotation": 1
    },
    {
      "x": -16,
      "y": 9,
      "z": -4,
      "name": "Rock_Volcanic",
      "rotation": 1
    },
    {
      "x": -16,
      "y": 10,
      "z": -4,
      "name": "Rock_Volcanic",
      "rotation": 1
    },
    {
      "x": -16,
      "y": 11,
      "z": -4,
      "name": "Rock_Volcanic",
      "rotation": 1
    },
    {
      "x": -16,
      "y": 12,
      "z": -4,
      "name": "Rock_Volcanic",
      "rotation": 1
    },
    {
      "x": -16,
      "y": 13,
      "z": -4,
      "name": "Rock_Volcanic",
      "rotation": 1
    },
    {
      "x": -16,
      "y": 14,
      "z": -4,
      "name": "Rock_Volcanic"
    },
    {
      "x": -16,
      "y": 15,
      "z": -4,
      "name": "Rock_Volcanic"
    },
    {
      "x": -16,
      "y": 16,
      "z": -4,
      "name": "Rock_Volcanic"
    },
    {
      "x": -16,
      "y": 17,
      "z": -4,
      "name": "Rock_Volcanic"
    },
    {
      "x": -16,
      "y": 18,
      "z": -4,
      "name": "Rock_Volcanic",
      "rotation": 1
    },
    {
      "x": -16,
      "y": 19,
      "z": -4,
